{
    DataVersion: 3465,
    size: [16, 13, 16],
    data: [
        {pos: [1, 0, 1], state: "minecraft:smooth_stone"},
        {pos: [1, 0, 2], state: "minecraft:smooth_stone"},
        {pos: [1, 0, 3], state: "minecraft:smooth_stone"},
        {pos: [1, 0, 4], state: "minecraft:smooth_stone"},
        {pos: [1, 0, 5], state: "minecraft:smooth_stone"},
        {pos: [1, 0, 6], state: "minecraft:smooth_stone"},
        {pos: [1, 0, 7], state: "minecraft:smooth_stone"},
        {pos: [1, 0, 8], state: "minecraft:smooth_stone"},
        {pos: [1, 0, 9], state: "minecraft:smooth_stone"},
        {pos: [1, 0, 10], state: "minecraft:smooth_stone"},
        {pos: [1, 0, 11], state: "minecraft:smooth_stone"},
        {pos: [1, 0, 12], state: "minecraft:smooth_stone"},
        {pos: [1, 0, 13], state: "minecraft:smooth_stone"},
        {pos: [1, 0, 14], state: "minecraft:smooth_stone"},
        {pos: [2, 0, 1], state: "minecraft:smooth_stone"},
        {pos: [2, 0, 2], state: "minecraft:sea_lantern"},
        {pos: [2, 0, 3], state: "minecraft:stone"},
        {pos: [2, 0, 4], state: "minecraft:stone"},
        {pos: [2, 0, 5], state: "minecraft:stone"},
        {pos: [2, 0, 6], state: "minecraft:stone"},
        {pos: [2, 0, 7], state: "minecraft:sea_lantern"},
        {pos: [2, 0, 8], state: "minecraft:sea_lantern"},
        {pos: [2, 0, 9], state: "minecraft:stone"},
        {pos: [2, 0, 10], state: "minecraft:stone"},
        {pos: [2, 0, 11], state: "minecraft:stone"},
        {pos: [2, 0, 12], state: "minecraft:stone"},
        {pos: [2, 0, 13], state: "minecraft:sea_lantern"},
        {pos: [2, 0, 14], state: "minecraft:smooth_stone"},
        {pos: [3, 0, 1], state: "minecraft:smooth_stone"},
        {pos: [3, 0, 2], state: "minecraft:stone"},
        {pos: [3, 0, 3], state: "minecraft:stone"},
        {pos: [3, 0, 4], state: "minecraft:stone"},
        {pos: [3, 0, 5], state: "minecraft:stone"},
        {pos: [3, 0, 6], state: "minecraft:stone"},
        {pos: [3, 0, 7], state: "minecraft:stone"},
        {pos: [3, 0, 8], state: "minecraft:stone"},
        {pos: [3, 0, 9], state: "minecraft:stone"},
        {pos: [3, 0, 10], state: "minecraft:stone"},
        {pos: [3, 0, 11], state: "minecraft:stone"},
        {pos: [3, 0, 12], state: "minecraft:stone"},
        {pos: [3, 0, 13], state: "minecraft:stone"},
        {pos: [3, 0, 14], state: "minecraft:smooth_stone"},
        {pos: [4, 0, 1], state: "minecraft:smooth_stone"},
        {pos: [4, 0, 2], state: "minecraft:stone"},
        {pos: [4, 0, 3], state: "minecraft:stone"},
        {pos: [4, 0, 4], state: "minecraft:stone"},
        {pos: [4, 0, 5], state: "minecraft:stone"},
        {pos: [4, 0, 6], state: "minecraft:stone"},
        {pos: [4, 0, 7], state: "minecraft:stone"},
        {pos: [4, 0, 8], state: "minecraft:stone"},
        {pos: [4, 0, 9], state: "minecraft:stone"},
        {pos: [4, 0, 10], state: "minecraft:stone"},
        {pos: [4, 0, 11], state: "minecraft:stone"},
        {pos: [4, 0, 12], state: "minecraft:stone"},
        {pos: [4, 0, 13], state: "minecraft:stone"},
        {pos: [4, 0, 14], state: "minecraft:smooth_stone"},
        {pos: [5, 0, 1], state: "minecraft:smooth_stone"},
        {pos: [5, 0, 2], state: "minecraft:stone"},
        {pos: [5, 0, 3], state: "minecraft:stone"},
        {pos: [5, 0, 4], state: "minecraft:stone"},
        {pos: [5, 0, 5], state: "minecraft:stone"},
        {pos: [5, 0, 6], state: "minecraft:stone"},
        {pos: [5, 0, 7], state: "minecraft:stone"},
        {pos: [5, 0, 8], state: "minecraft:stone"},
        {pos: [5, 0, 9], state: "minecraft:stone"},
        {pos: [5, 0, 10], state: "minecraft:stone"},
        {pos: [5, 0, 11], state: "minecraft:stone"},
        {pos: [5, 0, 12], state: "minecraft:stone"},
        {pos: [5, 0, 13], state: "minecraft:stone"},
        {pos: [5, 0, 14], state: "minecraft:smooth_stone"},
        {pos: [6, 0, 1], state: "minecraft:smooth_stone"},
        {pos: [6, 0, 2], state: "minecraft:stone"},
        {pos: [6, 0, 3], state: "minecraft:stone"},
        {pos: [6, 0, 4], state: "minecraft:stone"},
        {pos: [6, 0, 5], state: "minecraft:stone"},
        {pos: [6, 0, 6], state: "minecraft:stone"},
        {pos: [6, 0, 7], state: "minecraft:stone"},
        {pos: [6, 0, 8], state: "minecraft:stone"},
        {pos: [6, 0, 9], state: "minecraft:stone"},
        {pos: [6, 0, 10], state: "minecraft:stone"},
        {pos: [6, 0, 11], state: "minecraft:stone"},
        {pos: [6, 0, 12], state: "minecraft:stone"},
        {pos: [6, 0, 13], state: "minecraft:stone"},
        {pos: [6, 0, 14], state: "minecraft:smooth_stone"},
        {pos: [7, 0, 1], state: "minecraft:smooth_stone"},
        {pos: [7, 0, 2], state: "minecraft:sea_lantern"},
        {pos: [7, 0, 3], state: "minecraft:stone"},
        {pos: [7, 0, 4], state: "minecraft:stone"},
        {pos: [7, 0, 5], state: "minecraft:stone"},
        {pos: [7, 0, 6], state: "minecraft:stone"},
        {pos: [7, 0, 7], state: "minecraft:sea_lantern"},
        {pos: [7, 0, 8], state: "minecraft:sea_lantern"},
        {pos: [7, 0, 9], state: "minecraft:stone"},
        {pos: [7, 0, 10], state: "minecraft:stone"},
        {pos: [7, 0, 11], state: "minecraft:stone"},
        {pos: [7, 0, 12], state: "minecraft:stone"},
        {pos: [7, 0, 13], state: "minecraft:sea_lantern"},
        {pos: [7, 0, 14], state: "minecraft:smooth_stone"},
        {pos: [8, 0, 1], state: "minecraft:smooth_stone"},
        {pos: [8, 0, 2], state: "minecraft:sea_lantern"},
        {pos: [8, 0, 3], state: "minecraft:stone"},
        {pos: [8, 0, 4], state: "minecraft:stone"},
        {pos: [8, 0, 5], state: "minecraft:stone"},
        {pos: [8, 0, 6], state: "minecraft:stone"},
        {pos: [8, 0, 7], state: "minecraft:sea_lantern"},
        {pos: [8, 0, 8], state: "minecraft:sea_lantern"},
        {pos: [8, 0, 9], state: "minecraft:stone"},
        {pos: [8, 0, 10], state: "minecraft:stone"},
        {pos: [8, 0, 11], state: "minecraft:stone"},
        {pos: [8, 0, 12], state: "minecraft:stone"},
        {pos: [8, 0, 13], state: "minecraft:sea_lantern"},
        {pos: [8, 0, 14], state: "minecraft:smooth_stone"},
        {pos: [9, 0, 1], state: "minecraft:smooth_stone"},
        {pos: [9, 0, 2], state: "minecraft:stone"},
        {pos: [9, 0, 3], state: "minecraft:stone"},
        {pos: [9, 0, 4], state: "minecraft:stone"},
        {pos: [9, 0, 5], state: "minecraft:stone"},
        {pos: [9, 0, 6], state: "minecraft:stone"},
        {pos: [9, 0, 7], state: "minecraft:stone"},
        {pos: [9, 0, 8], state: "minecraft:stone"},
        {pos: [9, 0, 9], state: "minecraft:stone"},
        {pos: [9, 0, 10], state: "minecraft:stone"},
        {pos: [9, 0, 11], state: "minecraft:stone"},
        {pos: [9, 0, 12], state: "minecraft:stone"},
        {pos: [9, 0, 13], state: "minecraft:stone"},
        {pos: [9, 0, 14], state: "minecraft:smooth_stone"},
        {pos: [10, 0, 1], state: "minecraft:smooth_stone"},
        {pos: [10, 0, 2], state: "minecraft:stone"},
        {pos: [10, 0, 3], state: "minecraft:stone"},
        {pos: [10, 0, 4], state: "minecraft:stone"},
        {pos: [10, 0, 5], state: "minecraft:stone"},
        {pos: [10, 0, 6], state: "minecraft:stone"},
        {pos: [10, 0, 7], state: "minecraft:stone"},
        {pos: [10, 0, 8], state: "minecraft:stone"},
        {pos: [10, 0, 9], state: "minecraft:stone"},
        {pos: [10, 0, 10], state: "minecraft:stone"},
        {pos: [10, 0, 11], state: "minecraft:stone"},
        {pos: [10, 0, 12], state: "minecraft:stone"},
        {pos: [10, 0, 13], state: "minecraft:stone"},
        {pos: [10, 0, 14], state: "minecraft:smooth_stone"},
        {pos: [10, 0, 15], state: "minecraft:stone"},
        {pos: [11, 0, 1], state: "minecraft:smooth_stone"},
        {pos: [11, 0, 2], state: "minecraft:stone"},
        {pos: [11, 0, 3], state: "minecraft:stone"},
        {pos: [11, 0, 4], state: "minecraft:stone"},
        {pos: [11, 0, 5], state: "minecraft:stone"},
        {pos: [11, 0, 6], state: "minecraft:stone"},
        {pos: [11, 0, 7], state: "minecraft:stone"},
        {pos: [11, 0, 8], state: "minecraft:stone"},
        {pos: [11, 0, 9], state: "minecraft:stone"},
        {pos: [11, 0, 10], state: "minecraft:stone"},
        {pos: [11, 0, 11], state: "minecraft:stone"},
        {pos: [11, 0, 12], state: "minecraft:stone"},
        {pos: [11, 0, 13], state: "minecraft:stone"},
        {pos: [11, 0, 14], state: "minecraft:smooth_stone"},
        {pos: [11, 0, 15], state: "minecraft:stone"},
        {pos: [12, 0, 1], state: "minecraft:smooth_stone"},
        {pos: [12, 0, 2], state: "minecraft:stone"},
        {pos: [12, 0, 3], state: "minecraft:stone"},
        {pos: [12, 0, 4], state: "minecraft:stone"},
        {pos: [12, 0, 5], state: "minecraft:stone"},
        {pos: [12, 0, 6], state: "minecraft:stone"},
        {pos: [12, 0, 7], state: "minecraft:stone"},
        {pos: [12, 0, 8], state: "minecraft:stone"},
        {pos: [12, 0, 9], state: "minecraft:stone"},
        {pos: [12, 0, 10], state: "minecraft:stone"},
        {pos: [12, 0, 11], state: "minecraft:stone"},
        {pos: [12, 0, 12], state: "minecraft:stone"},
        {pos: [12, 0, 13], state: "minecraft:stone"},
        {pos: [12, 0, 14], state: "minecraft:smooth_stone"},
        {pos: [12, 0, 15], state: "minecraft:stone"},
        {pos: [13, 0, 1], state: "minecraft:smooth_stone"},
        {pos: [13, 0, 2], state: "minecraft:sea_lantern"},
        {pos: [13, 0, 3], state: "minecraft:stone"},
        {pos: [13, 0, 4], state: "minecraft:stone"},
        {pos: [13, 0, 5], state: "minecraft:stone"},
        {pos: [13, 0, 6], state: "minecraft:stone"},
        {pos: [13, 0, 7], state: "minecraft:sea_lantern"},
        {pos: [13, 0, 8], state: "minecraft:sea_lantern"},
        {pos: [13, 0, 9], state: "minecraft:stone"},
        {pos: [13, 0, 10], state: "minecraft:stone"},
        {pos: [13, 0, 11], state: "minecraft:stone"},
        {pos: [13, 0, 12], state: "minecraft:stone"},
        {pos: [13, 0, 13], state: "minecraft:sea_lantern"},
        {pos: [13, 0, 14], state: "minecraft:smooth_stone"},
        {pos: [13, 0, 15], state: "minecraft:stone"},
        {pos: [14, 0, 1], state: "minecraft:smooth_stone"},
        {pos: [14, 0, 2], state: "minecraft:smooth_stone"},
        {pos: [14, 0, 3], state: "minecraft:smooth_stone"},
        {pos: [14, 0, 4], state: "minecraft:smooth_stone"},
        {pos: [14, 0, 5], state: "minecraft:smooth_stone"},
        {pos: [14, 0, 6], state: "minecraft:smooth_stone"},
        {pos: [14, 0, 7], state: "minecraft:smooth_stone"},
        {pos: [14, 0, 8], state: "minecraft:smooth_stone"},
        {pos: [14, 0, 9], state: "minecraft:smooth_stone"},
        {pos: [14, 0, 10], state: "minecraft:smooth_stone"},
        {pos: [14, 0, 11], state: "minecraft:smooth_stone"},
        {pos: [14, 0, 12], state: "minecraft:smooth_stone"},
        {pos: [14, 0, 13], state: "minecraft:smooth_stone"},
        {pos: [14, 0, 14], state: "minecraft:smooth_stone"},
        {pos: [14, 0, 15], state: "minecraft:stone"},
        {pos: [15, 0, 4], state: "minecraft:stone"},
        {pos: [15, 0, 5], state: "minecraft:stone"},
        {pos: [15, 0, 6], state: "minecraft:stone"},
        {pos: [15, 0, 7], state: "minecraft:stone"},
        {pos: [15, 0, 8], state: "minecraft:stone"},
        {pos: [15, 0, 9], state: "minecraft:stone"},
        {pos: [15, 0, 10], state: "minecraft:stone"},
        {pos: [15, 0, 11], state: "minecraft:stone"},
        {pos: [15, 0, 12], state: "minecraft:stone"},
        {pos: [15, 0, 13], state: "minecraft:stone"},
        {pos: [15, 0, 14], state: "minecraft:stone"},
        {pos: [15, 0, 15], state: "minecraft:stone"},
        {pos: [2, 1, 10], state: "minecraft:netherite_block"},
        {pos: [2, 1, 11], state: "minecraft:netherite_block"},
        {pos: [2, 1, 12], state: "minecraft:netherite_block"},
        {pos: [3, 1, 10], state: "tl2:creative_energy_cell", nbt: {id: "tl2:creative_energy_cell", proxy: {p: 0}, visual: {}}},
        {pos: [3, 1, 11], state: "minecraft:netherite_block"},
        {pos: [3, 1, 12], state: "minecraft:netherite_block"},
        {pos: [4, 1, 2], state: "minecraft:hopper{enabled:true,facing:south}", nbt: {Items: [], TransferCooldown: 0, id: "minecraft:hopper"}},
        {pos: [4, 1, 3], state: "minecraft:hopper{enabled:true,facing:south}", nbt: {Items: [], TransferCooldown: 0, id: "minecraft:hopper"}},
        {pos: [4, 1, 4], state: "minecraft:hopper{enabled:true,facing:south}", nbt: {Items: [], TransferCooldown: 0, id: "minecraft:hopper"}},
        {pos: [4, 1, 5], state: "minecraft:hopper{enabled:true,facing:south}", nbt: {Items: [], TransferCooldown: 0, id: "minecraft:hopper"}},
        {pos: [4, 1, 6], state: "minecraft:hopper{enabled:true,facing:south}", nbt: {Items: [], TransferCooldown: 0, id: "minecraft:hopper"}},
        {pos: [4, 1, 7], state: "minecraft:hopper{enabled:true,facing:east}", nbt: {Items: [], TransferCooldown: 0, id: "minecraft:hopper"}},
        {pos: [4, 1, 10], state: "tl2:energy_acceptor", nbt: {id: "tl2:energy_acceptor", internalCurrentPower: 0.0d, proxy: {p: 0}, visual: {}}},
        {pos: [5, 1, 6], state: "tl2:cable_bus{light_level:0,waterlogged:false}", nbt: {cable: {gn: {p: 0}, id: "tl2:orange_smart_cable", visual: {channelsEast: 1, channelsUp: 1, connections: ["up", "east"], missingChannel: 0b, powered: 1b}}, hasRedstone: 2, id: "tl2:cable_bus", visual: {}}},
        {pos: [5, 1, 7], state: "minecraft:hopper{enabled:true,facing:east}", nbt: {Items: [], TransferCooldown: 0, id: "minecraft:hopper"}},
        {pos: [5, 1, 10], state: "tl2:cable_bus{light_level:0,waterlogged:false}", nbt: {cable: {gn: {p: 0}, id: "tl2:white_smart_dense_cable", visual: {channelsEast: 0, channelsWest: 0, connections: ["west", "east"], missingChannel: 0b, powered: 1b}}, hasRedstone: 2, id: "tl2:cable_bus", visual: {}}},
        {pos: [6, 1, 6], state: "tl2:cable_bus{light_level:0,waterlogged:false}", nbt: {cable: {gn: {p: 0}, id: "tl2:orange_smart_cable", visual: {channelsWest: 1, connections: ["west"], missingChannel: 0b, powered: 1b}}, hasRedstone: 2, id: "tl2:cable_bus", south: {fuzzy_mode: "IGNORE_ALL", gn: {p: 0}, id: "tl2:cable_interface", priority: 0, visual: {missingChannel: 0b, powered: 1b}}, visual: {}}},
        {pos: [6, 1, 7], state: "tl2:pattern_provider{push_direction:north}", nbt: {blocking_mode: "NO", id: "tl2:pattern_provider", lock_crafting_mode: "NONE", pattern_access_terminal: "YES", priority: 0, proxy: {p: 0}, returnInv: [], sendList: [], visual: {}}},
        {pos: [6, 1, 10], state: "tl2:cable_bus{light_level:0,waterlogged:false}", nbt: {cable: {gn: {p: 0}, id: "tl2:white_smart_dense_cable", visual: {channelsEast: 0, channelsWest: 0, connections: ["west", "east"], missingChannel: 0b, powered: 1b}}, hasRedstone: 2, id: "tl2:cable_bus", visual: {}}},
        {pos: [6, 1, 12], state: "tl2:molecular_assembler{powered:true}", nbt: {id: "tl2:molecular_assembler", inv: {item0: {}, item1: {}, item10: {}, item2: {}, item3: {}, item4: {}, item5: {}, item6: {}, item7: {}, item8: {}, item9: {}}, proxy: {p: 0}, visual: {}}},
        {pos: [7, 1, 4], state: "tl2:cable_bus{light_level:0,waterlogged:false}", nbt: {cable: {gn: {p: 0}, id: "tl2:orange_smart_cable", visual: {channelsSouth: 4, connections: ["south"], missingChannel: 0b, powered: 1b}}, hasRedstone: 2, id: "tl2:cable_bus", up: {gn: {p: 0}, id: "tl2:annihilation_plane", visual: {missingChannel: 0b, powered: 1b}}, visual: {}}},
        {pos: [7, 1, 5], state: "tl2:cable_bus{light_level:0,waterlogged:false}", nbt: {cable: {gn: {p: 0}, id: "tl2:orange_smart_cable", visual: {channelsEast: 4, channelsNorth: 4, connections: ["north", "east"], missingChannel: 0b, powered: 1b}}, hasRedstone: 2, id: "tl2:cable_bus", visual: {}}},
        {pos: [7, 1, 10], state: "tl2:cable_bus{light_level:0,waterlogged:false}", nbt: {cable: {gn: {p: 0}, id: "tl2:white_smart_dense_cable", visual: {channelsEast: 8, channelsSouth: 0, channelsUp: 8, channelsWest: 0, connections: ["up", "south", "west", "east"], missingChannel: 0b, powered: 1b}}, hasRedstone: 2, id: "tl2:cable_bus", visual: {}}},
        {pos: [7, 1, 11], state: "tl2:molecular_assembler{powered:true}", nbt: {id: "tl2:molecular_assembler", inv: {item0: {}, item1: {}, item10: {}, item2: {}, item3: {}, item4: {}, item5: {}, item6: {}, item7: {}, item8: {}, item9: {}}, proxy: {p: 0}, visual: {}}},
        {pos: [8, 1, 3], state: "tl2:cable_bus{light_level:0,waterlogged:false}", nbt: {cable: {gn: {p: 0}, id: "tl2:orange_smart_cable", visual: {channelsSouth: 4, connections: ["south"], missingChannel: 0b, powered: 1b}}, hasRedstone: 2, id: "tl2:cable_bus", up: {gn: {p: 0}, id: "tl2:annihilation_plane", visual: {missingChannel: 0b, powered: 1b}}, visual: {}}},
        {pos: [8, 1, 4], state: "tl2:growth_accelerator{facing:north,powered:true}", nbt: {id: "tl2:growth_accelerator", proxy: {p: 0}, visual: {}}},
        {pos: [8, 1, 5], state: "tl2:cable_bus{light_level:0,waterlogged:false}", nbt: {cable: {gn: {p: 0}, id: "tl2:orange_smart_cable", visual: {channelsEast: 4, channelsNorth: 4, channelsUp: 4, channelsWest: 4, connections: ["up", "north", "west", "east"], missingChannel: 0b, powered: 1b}}, hasRedstone: 2, id: "tl2:cable_bus", visual: {}}},
        {pos: [8, 1, 10], state: "tl2:cable_bus{light_level:0,waterlogged:false}", nbt: {cable: {gn: {p: 0}, id: "tl2:white_smart_dense_cable", visual: {channelsEast: 8, channelsWest: 8, connections: ["west", "east"], missingChannel: 0b, powered: 1b}}, hasRedstone: 2, id: "tl2:cable_bus", visual: {}}},
        {pos: [9, 1, 4], state: "tl2:cable_bus{light_level:0,waterlogged:false}", nbt: {cable: {gn: {p: 0}, id: "tl2:orange_smart_cable", visual: {channelsSouth: 4, connections: ["south"], missingChannel: 0b, powered: 1b}}, hasRedstone: 2, id: "tl2:cable_bus", up: {gn: {p: 0}, id: "tl2:annihilation_plane", visual: {missingChannel: 0b, powered: 1b}}, visual: {}}},
        {pos: [9, 1, 5], state: "tl2:cable_bus{light_level:0,waterlogged:false}", nbt: {cable: {gn: {p: 0}, id: "tl2:orange_smart_cable", visual: {channelsNorth: 4, channelsWest: 4, connections: ["north", "west"], missingChannel: 0b, powered: 1b}}, hasRedstone: 2, id: "tl2:cable_bus", visual: {}}},
        {pos: [9, 1, 9], state: "minecraft:stone_brick_stairs{facing:south,half:bottom,shape:straight,waterlogged:false}"},
        {pos: [9, 1, 10], state: "tl2:cable_bus{light_level:0,waterlogged:false}", nbt: {cable: {gn: {p: 0}, id: "tl2:white_smart_dense_cable", visual: {channelsEast: 8, channelsWest: 8, connections: ["west", "east"], missingChannel: 0b, powered: 1b}}, facadeUp: {Name: "minecraft:stone_bricks"}, hasRedstone: 2, id: "tl2:cable_bus", visual: {}}},
        {pos: [9, 1, 11], state: "minecraft:stone_brick_stairs{facing:north,half:bottom,shape:straight,waterlogged:false}"},
        {pos: [10, 1, 10], state: "tl2:cable_bus{light_level:0,waterlogged:false}", nbt: {cable: {gn: {p: 0}, id: "tl2:white_smart_dense_cable", visual: {channelsEast: 8, channelsWest: 8, connections: ["west", "east"], missingChannel: 0b, powered: 1b}}, hasRedstone: 2, id: "tl2:cable_bus", visual: {}}},
        {pos: [10, 1, 15], state: "minecraft:stone"},
        {pos: [11, 1, 3], state: "tl2:cable_bus{light_level:0,waterlogged:false}", nbt: {cable: {gn: {p: 0}, id: "tl2:green_smart_cable", visual: {channelsEast: 2, connections: ["east"], missingChannel: 0b, powered: 1b}}, hasRedstone: 2, id: "tl2:cable_bus", south: {fuzzy_mode: "IGNORE_ALL", gn: {p: 0}, id: "tl2:cable_interface", priority: 0, visual: {missingChannel: 0b, powered: 1b}}, up: {fuzzy_mode: "IGNORE_ALL", gn: {p: 0}, id: "tl2:formation_plane", place_block: "YES", priority: 0, visual: {missingChannel: 0b, powered: 1b}}, visual: {}}},
        {pos: [11, 1, 4], state: "tl2:pattern_provider{push_direction:all}", nbt: {blocking_mode: "NO", id: "tl2:pattern_provider", lock_crafting_mode: "NONE", pattern_access_terminal: "YES", priority: 0, proxy: {p: 0}, returnInv: [], sendList: [], visual: {}}},
        {pos: [11, 1, 5], state: "tl2:cable_bus{light_level:0,waterlogged:false}", nbt: {cable: {gn: {p: 0}, id: "tl2:blue_smart_cable", visual: {channelsNorth: 1, channelsUp: 1, connections: ["up", "north"], missingChannel: 0b, powered: 1b}}, hasRedstone: 2, id: "tl2:cable_bus", visual: {}}},
        {pos: [11, 1, 10], state: "tl2:cable_bus{light_level:0,waterlogged:false}", nbt: {cable: {gn: {p: 0}, id: "tl2:white_smart_dense_cable", visual: {channelsEast: 16, channelsSouth: 0, channelsUp: 8, channelsWest: 8, connections: ["up", "south", "west", "east"], missingChannel: 0b, powered: 1b}}, hasRedstone: 2, id: "tl2:cable_bus", visual: {}}},
        {pos: [11, 1, 11], state: "tl2:molecular_assembler{powered:true}", nbt: {id: "tl2:molecular_assembler", inv: {item0: {}, item1: {}, item10: {}, item2: {}, item3: {}, item4: {}, item5: {}, item6: {}, item7: {}, item8: {}, item9: {}}, proxy: {p: 0}, visual: {}}},
        {pos: [11, 1, 15], state: "minecraft:stone"},
        {pos: [12, 1, 3], state: "tl2:cable_bus{light_level:0,waterlogged:false}", nbt: {cable: {gn: {p: 0}, id: "tl2:green_smart_cable", visual: {channelsWest: 2, connections: ["west"], missingChannel: 0b, powered: 1b}}, hasRedstone: 2, id: "tl2:cable_bus", south: {gn: {p: 0}, id: "tl2:quartz_fiber", outer: {p: 0}, visual: {missingChannel: 0b, powered: 1b}}, visual: {}}},
        {pos: [12, 1, 4], state: "tl2:cable_bus{light_level:0,waterlogged:false}", nbt: {cable: {gn: {p: 0}, id: "tl2:blue_smart_cable", visual: {channelsNorth: 0, channelsUp: 0, channelsWest: 0, connections: ["up", "north", "west"], missingChannel: 0b, powered: 1b}}, hasRedstone: 2, id: "tl2:cable_bus", visual: {}}},
        {pos: [12, 1, 10], state: "tl2:cable_bus{light_level:0,waterlogged:false}", nbt: {cable: {gn: {p: 0}, id: "tl2:white_smart_dense_cable", visual: {channelsEast: 16, channelsWest: 16, connections: ["west", "east"], missingChannel: 0b, powered: 1b}}, hasRedstone: 2, id: "tl2:cable_bus", visual: {}}},
        {pos: [12, 1, 12], state: "tl2:molecular_assembler{powered:true}", nbt: {id: "tl2:molecular_assembler", inv: {item0: {}, item1: {}, item10: {}, item2: {}, item3: {}, item4: {}, item5: {}, item6: {}, item7: {}, item8: {}, item9: {}}, proxy: {p: 0}, visual: {}}},
        {pos: [12, 1, 15], state: "minecraft:stone"},
        {pos: [13, 1, 10], state: "tl2:cable_bus{light_level:0,waterlogged:false}", nbt: {cable: {gn: {p: 0}, id: "tl2:white_smart_dense_cable", visual: {channelsEast: 16, channelsWest: 16, connections: ["west", "east"], missingChannel: 0b, powered: 1b}}, hasRedstone: 2, id: "tl2:cable_bus", visual: {}}},
        {pos: [13, 1, 15], state: "minecraft:stone"},
        {pos: [14, 1, 2], state: "tl2:crafting_accelerator{formed:true,powered:true}", nbt: {core: 1b, crafting_scheduling_mode: "ANY", id: "tl2:crafting_unit", inventory: [], proxy: {p: 0}, visual: {}}},
        {pos: [14, 1, 4], state: "tl2:crafting_accelerator{formed:true,powered:true}", nbt: {core: 1b, crafting_scheduling_mode: "ANY", id: "tl2:crafting_unit", inventory: [], proxy: {p: 0}, visual: {}}},
        {pos: [14, 1, 6], state: "tl2:crafting_accelerator{formed:true,powered:true}", nbt: {core: 1b, crafting_scheduling_mode: "ANY", id: "tl2:crafting_unit", inventory: [], proxy: {p: 0}, visual: {}}},
        {pos: [14, 1, 9], state: "minecraft:ladder{facing:west,waterlogged:false}"},
        {pos: [14, 1, 10], state: "tl2:cable_bus{light_level:0,waterlogged:false}", nbt: {cable: {gn: {p: 0}, id: "tl2:white_smart_dense_cable", visual: {channelsEast: 16, channelsWest: 16, connections: ["west", "east"], missingChannel: 0b, powered: 1b}}, hasRedstone: 2, id: "tl2:cable_bus", visual: {}}},
        {pos: [14, 1, 15], state: "minecraft:stone"},
        {pos: [15, 1, 4], state: "minecraft:stone"},
        {pos: [15, 1, 5], state: "minecraft:stone"},
        {pos: [15, 1, 6], state: "tl2:crafting_accelerator{formed:true,powered:true}", nbt: {core: 0b, id: "tl2:crafting_unit", proxy: {p: 0}, visual: {}}},
        {pos: [15, 1, 7], state: "minecraft:stone"},
        {pos: [15, 1, 8], state: "minecraft:stone"},
        {pos: [15, 1, 9], state: "minecraft:stone"},
        {pos: [15, 1, 10], state: "tl2:cable_bus{light_level:0,waterlogged:false}", nbt: {cable: {gn: {p: 0}, id: "tl2:white_smart_dense_cable", visual: {channelsSouth: 16, channelsWest: 16, connections: ["south", "west"], missingChannel: 0b, powered: 1b}}, facadeWest: {Name: "minecraft:stone_bricks"}, hasRedstone: 2, id: "tl2:cable_bus", visual: {}}},
        {pos: [15, 1, 11], state: "tl2:cable_bus{light_level:0,waterlogged:false}", nbt: {cable: {gn: {p: 0}, id: "tl2:white_smart_dense_cable", visual: {channelsNorth: 16, channelsSouth: 16, connections: ["north", "south"], missingChannel: 0b, powered: 1b}}, facadeWest: {Name: "minecraft:stone_bricks"}, hasRedstone: 2, id: "tl2:cable_bus", visual: {}}},
        {pos: [15, 1, 12], state: "tl2:cable_bus{light_level:0,waterlogged:false}", nbt: {cable: {gn: {p: 0}, id: "tl2:white_smart_dense_cable", visual: {channelsNorth: 16, channelsSouth: 16, connections: ["north", "south"], missingChannel: 0b, powered: 1b}}, facadeWest: {Name: "minecraft:stone_bricks"}, hasRedstone: 2, id: "tl2:cable_bus", visual: {}}},
        {pos: [15, 1, 13], state: "tl2:cable_bus{light_level:0,waterlogged:false}", nbt: {cable: {gn: {p: 0}, id: "tl2:white_smart_dense_cable", visual: {channelsNorth: 16, channelsUp: 16, connections: ["up", "north"], missingChannel: 0b, powered: 1b}}, facadeWest: {Name: "minecraft:stone_bricks"}, hasRedstone: 2, id: "tl2:cable_bus", visual: {}}},
        {pos: [15, 1, 14], state: "minecraft:stone"},
        {pos: [15, 1, 15], state: "minecraft:stone"},
        {pos: [2, 2, 10], state: "minecraft:iron_block"},
        {pos: [2, 2, 11], state: "minecraft:iron_block"},
        {pos: [2, 2, 12], state: "minecraft:netherite_block"},
        {pos: [3, 2, 10], state: "minecraft:redstone_block"},
        {pos: [3, 2, 11], state: "minecraft:iron_block"},
        {pos: [3, 2, 12], state: "minecraft:netherite_block"},
        {pos: [4, 2, 2], state: "minecraft:furnace{facing:west,lit:false}", nbt: {BurnTime: 0s, CookTime: 0s, CookTimeTotal: 0s, Items: [], RecipesUsed: {}, id: "minecraft:furnace"}},
        {pos: [4, 2, 3], state: "minecraft:furnace{facing:west,lit:false}", nbt: {BurnTime: 0s, CookTime: 0s, CookTimeTotal: 0s, Items: [], RecipesUsed: {}, id: "minecraft:furnace"}},
        {pos: [4, 2, 4], state: "minecraft:furnace{facing:west,lit:false}", nbt: {BurnTime: 0s, CookTime: 0s, CookTimeTotal: 0s, Items: [], RecipesUsed: {}, id: "minecraft:furnace"}},
        {pos: [4, 2, 5], state: "minecraft:furnace{facing:west,lit:false}", nbt: {BurnTime: 0s, CookTime: 0s, CookTimeTotal: 0s, Items: [], RecipesUsed: {}, id: "minecraft:furnace"}},
        {pos: [4, 2, 6], state: "minecraft:furnace{facing:west,lit:false}", nbt: {BurnTime: 0s, CookTime: 0s, CookTimeTotal: 0s, Items: [], RecipesUsed: {}, id: "minecraft:furnace"}},
        {pos: [4, 2, 7], state: "minecraft:furnace{facing:west,lit:false}", nbt: {BurnTime: 0s, CookTime: 0s, CookTimeTotal: 0s, Items: [], RecipesUsed: {}, id: "minecraft:furnace"}},
        {pos: [5, 2, 2], state: "tl2:cable_bus{light_level:0,waterlogged:false}", nbt: {cable: {gn: {p: 0}, id: "tl2:orange_smart_cable", visual: {channelsSouth: 1, connections: ["south"], missingChannel: 0b, powered: 1b}}, hasRedstone: 2, id: "tl2:cable_bus", visual: {}, west: {access: "READ_WRITE", filter_on_extract: "YES", fuzzy_mode: "IGNORE_ALL", gn: {p: 0}, id: "tl2:storage_bus", priority: 0, storage_filter: "EXTRACTABLE_ONLY", visual: {missingChannel: 0b, powered: 1b}}}},
        {pos: [5, 2, 3], state: "tl2:cable_bus{light_level:0,waterlogged:false}", nbt: {cable: {gn: {p: 0}, id: "tl2:orange_smart_cable", visual: {channelsNorth: 1, channelsSouth: 2, connections: ["north", "south"], missingChannel: 0b, powered: 1b}}, hasRedstone: 2, id: "tl2:cable_bus", visual: {}, west: {access: "READ_WRITE", filter_on_extract: "YES", fuzzy_mode: "IGNORE_ALL", gn: {p: 0}, id: "tl2:storage_bus", priority: 0, storage_filter: "EXTRACTABLE_ONLY", visual: {missingChannel: 0b, powered: 1b}}}},
        {pos: [5, 2, 4], state: "tl2:cable_bus{light_level:0,waterlogged:false}", nbt: {cable: {gn: {p: 0}, id: "tl2:orange_smart_cable", visual: {channelsNorth: 2, channelsSouth: 3, connections: ["north", "south"], missingChannel: 0b, powered: 1b}}, hasRedstone: 2, id: "tl2:cable_bus", visual: {}, west: {access: "READ_WRITE", filter_on_extract: "YES", fuzzy_mode: "IGNORE_ALL", gn: {p: 0}, id: "tl2:storage_bus", priority: 0, storage_filter: "EXTRACTABLE_ONLY", visual: {missingChannel: 0b, powered: 1b}}}},
        {pos: [5, 2, 5], state: "tl2:cable_bus{light_level:0,waterlogged:false}", nbt: {cable: {gn: {p: 0}, id: "tl2:orange_smart_cable", visual: {channelsNorth: 3, channelsSouth: 4, connections: ["north", "south"], missingChannel: 0b, powered: 1b}}, hasRedstone: 2, id: "tl2:cable_bus", visual: {}, west: {access: "READ_WRITE", filter_on_extract: "YES", fuzzy_mode: "IGNORE_ALL", gn: {p: 0}, id: "tl2:storage_bus", priority: 0, storage_filter: "EXTRACTABLE_ONLY", visual: {missingChannel: 0b, powered: 1b}}}},
        {pos: [5, 2, 6], state: "tl2:cable_bus{light_level:0,waterlogged:false}", nbt: {cable: {gn: {p: 0}, id: "tl2:orange_smart_cable", visual: {channelsDown: 1, channelsNorth: 4, channelsSouth: 1, channelsUp: 7, connections: ["down", "up", "north", "south"], missingChannel: 0b, powered: 1b}}, hasRedstone: 2, id: "tl2:cable_bus", visual: {}, west: {access: "READ_WRITE", filter_on_extract: "YES", fuzzy_mode: "IGNORE_ALL", gn: {p: 0}, id: "tl2:storage_bus", priority: 0, storage_filter: "EXTRACTABLE_ONLY", visual: {missingChannel: 0b, powered: 1b}}}},
        {pos: [5, 2, 7], state: "tl2:cable_bus{light_level:0,waterlogged:false}", nbt: {cable: {gn: {p: 0}, id: "tl2:orange_smart_cable", visual: {channelsEast: 0, channelsNorth: 1, connections: ["north", "east"], missingChannel: 0b, powered: 1b}}, hasRedstone: 2, id: "tl2:cable_bus", visual: {}, west: {access: "READ_WRITE", filter_on_extract: "YES", fuzzy_mode: "IGNORE_ALL", gn: {p: 0}, id: "tl2:storage_bus", priority: 0, storage_filter: "EXTRACTABLE_ONLY", visual: {missingChannel: 0b, powered: 1b}}}},
        {pos: [5, 2, 12], state: "tl2:molecular_assembler{powered:true}", nbt: {id: "tl2:molecular_assembler", inv: {item0: {}, item1: {}, item10: {}, item2: {}, item3: {}, item4: {}, item5: {}, item6: {}, item7: {}, item8: {}, item9: {}}, proxy: {p: 0}, visual: {}}},
        {pos: [6, 2, 7], state: "tl2:cable_bus{light_level:0,waterlogged:false}", nbt: {cable: {gn: {p: 0}, id: "tl2:blue_smart_cable", visual: {channelsDown: 1, channelsUp: 1, connections: ["down", "up"], missingChannel: 0b, powered: 1b}}, hasRedstone: 2, id: "tl2:cable_bus", visual: {}, west: {gn: {p: 0}, id: "tl2:quartz_fiber", outer: {p: 0}, visual: {missingChannel: 0b, powered: 1b}}}},
        {pos: [6, 2, 11], state: "tl2:molecular_assembler{powered:true}", nbt: {id: "tl2:molecular_assembler", inv: {item0: {}, item1: {}, item10: {}, item2: {}, item3: {}, item4: {}, item5: {}, item6: {}, item7: {}, item8: {}, item9: {}}, proxy: {p: 0}, visual: {}}},
        {pos: [6, 2, 12], state: "tl2:pattern_provider{push_direction:all}", nbt: {blocking_mode: "NO", id: "tl2:pattern_provider", lock_crafting_mode: "NONE", pattern_access_terminal: "YES", priority: 0, proxy: {p: 0}, returnInv: [], sendList: [], visual: {}}},
        {pos: [6, 2, 13], state: "tl2:molecular_assembler{powered:true}", nbt: {id: "tl2:molecular_assembler", inv: {item0: {}, item1: {}, item10: {}, item2: {}, item3: {}, item4: {}, item5: {}, item6: {}, item7: {}, item8: {}, item9: {}}, proxy: {p: 0}, visual: {}}},
        {pos: [7, 2, 4], state: "tl2:medium_quartz_bud{facing:west,waterlogged:false}"},
        {pos: [7, 2, 10], state: "tl2:molecular_assembler{powered:true}", nbt: {id: "tl2:molecular_assembler", inv: {item0: {}, item1: {}, item10: {}, item2: {}, item3: {}, item4: {}, item5: {}, item6: {}, item7: {}, item8: {}, item9: {}}, proxy: {p: 0}, visual: {}}},
        {pos: [7, 2, 11], state: "tl2:pattern_provider{push_direction:all}", nbt: {blocking_mode: "NO", id: "tl2:pattern_provider", lock_crafting_mode: "NONE", pattern_access_terminal: "YES", priority: 0, proxy: {p: 0}, returnInv: [], sendList: [], visual: {}}},
        {pos: [7, 2, 12], state: "tl2:molecular_assembler{powered:true}", nbt: {id: "tl2:molecular_assembler", inv: {item0: {}, item1: {}, item10: {}, item2: {}, item3: {}, item4: {}, item5: {}, item6: {}, item7: {}, item8: {}, item9: {}}, proxy: {p: 0}, visual: {}}},
        {pos: [8, 2, 3], state: "tl2:medium_quartz_bud{facing:north,waterlogged:false}"},
        {pos: [8, 2, 4], state: "tl2:flawless_budding_quartz"},
        {pos: [8, 2, 5], state: "tl2:growth_accelerator{facing:up,powered:true}", nbt: {id: "tl2:growth_accelerator", proxy: {p: 0}, visual: {}}},
        {pos: [8, 2, 11], state: "tl2:molecular_assembler{powered:true}", nbt: {id: "tl2:molecular_assembler", inv: {item0: {}, item1: {}, item10: {}, item2: {}, item3: {}, item4: {}, item5: {}, item6: {}, item7: {}, item8: {}, item9: {}}, proxy: {p: 0}, visual: {}}},
        {pos: [9, 2, 4], state: "tl2:medium_quartz_bud{facing:east,waterlogged:false}"},
        {pos: [9, 2, 15], state: "minecraft:stone"},
        {pos: [10, 2, 2], state: "tl2:quartz_glass"},
        {pos: [10, 2, 3], state: "tl2:quartz_glass"},
        {pos: [10, 2, 11], state: "tl2:molecular_assembler{powered:true}", nbt: {id: "tl2:molecular_assembler", inv: {item0: {}, item1: {}, item10: {}, item2: {}, item3: {}, item4: {}, item5: {}, item6: {}, item7: {}, item8: {}, item9: {}}, proxy: {p: 0}, visual: {}}},
        {pos: [10, 2, 15], state: "minecraft:stone"},
        {pos: [11, 2, 2], state: "tl2:quartz_glass"},
        {pos: [11, 2, 3], state: "minecraft:water{level:0}"},
        {pos: [11, 2, 4], state: "tl2:cable_bus{light_level:0,waterlogged:false}", nbt: {cable: {gn: {p: 0}, id: "tl2:orange_smart_cable", visual: {channelsEast: 2, channelsUp: 2, connections: ["up", "east"], missingChannel: 0b, powered: 1b}}, down: {access: "READ_WRITE", config: [{"#": 0L, "#t": "tl2:i", id: "tl2:fluix_crystal"}], filter_on_extract: "YES", fuzzy_mode: "IGNORE_ALL", gn: {p: 0}, id: "tl2:storage_bus", priority: 0, storage_filter: "EXTRACTABLE_ONLY", visual: {missingChannel: 0b, powered: 1b}}, facadeNorth: {Name: "tl2:quartz_glass"}, hasRedstone: 2, id: "tl2:cable_bus", visual: {}}},
        {pos: [11, 2, 5], state: "tl2:cable_bus{light_level:0,waterlogged:false}", nbt: {cable: {gn: {p: 0}, id: "tl2:blue_smart_cable", visual: {channelsDown: 1, channelsUp: 1, connections: ["down", "up"], missingChannel: 0b, powered: 1b}}, hasRedstone: 2, id: "tl2:cable_bus", visual: {}}},
        {pos: [11, 2, 10], state: "tl2:molecular_assembler{powered:true}", nbt: {id: "tl2:molecular_assembler", inv: {item0: {}, item1: {}, item10: {}, item2: {}, item3: {}, item4: {}, item5: {}, item6: {}, item7: {}, item8: {}, item9: {}}, proxy: {p: 0}, visual: {}}},
        {pos: [11, 2, 11], state: "tl2:pattern_provider{push_direction:all}", nbt: {blocking_mode: "NO", id: "tl2:pattern_provider", lock_crafting_mode: "NONE", pattern_access_terminal: "YES", priority: 0, proxy: {p: 0}, returnInv: [], sendList: [], visual: {}}},
        {pos: [11, 2, 12], state: "tl2:molecular_assembler{powered:true}", nbt: {id: "tl2:molecular_assembler", inv: {item0: {}, item1: {}, item10: {}, item2: {}, item3: {}, item4: {}, item5: {}, item6: {}, item7: {}, item8: {}, item9: {}}, proxy: {p: 0}, visual: {}}},
        {pos: [11, 2, 15], state: "minecraft:stone"},
        {pos: [12, 2, 2], state: "tl2:quartz_glass"},
        {pos: [12, 2, 3], state: "tl2:quartz_glass"},
        {pos: [12, 2, 4], state: "tl2:cable_bus{light_level:0,waterlogged:false}", nbt: {cable: {gn: {p: 0}, id: "tl2:orange_smart_cable", visual: {channelsWest: 2, connections: ["west"], missingChannel: 0b, powered: 1b}}, down: {gn: {p: 0}, id: "tl2:quartz_fiber", outer: {p: 0}, visual: {missingChannel: 0b, powered: 1b}}, hasRedstone: 2, id: "tl2:cable_bus", visual: {}}},
        {pos: [12, 2, 11], state: "tl2:molecular_assembler{powered:true}", nbt: {id: "tl2:molecular_assembler", inv: {item0: {}, item1: {}, item10: {}, item2: {}, item3: {}, item4: {}, item5: {}, item6: {}, item7: {}, item8: {}, item9: {}}, proxy: {p: 0}, visual: {}}},
        {pos: [12, 2, 12], state: "tl2:pattern_provider{push_direction:all}", nbt: {blocking_mode: "NO", id: "tl2:pattern_provider", lock_crafting_mode: "NONE", pattern_access_terminal: "YES", priority: 0, proxy: {p: 0}, returnInv: [], sendList: [], visual: {}}},
        {pos: [12, 2, 13], state: "tl2:molecular_assembler{powered:true}", nbt: {id: "tl2:molecular_assembler", inv: {item0: {}, item1: {}, item10: {}, item2: {}, item3: {}, item4: {}, item5: {}, item6: {}, item7: {}, item8: {}, item9: {}}, proxy: {p: 0}, visual: {}}},
        {pos: [12, 2, 15], state: "minecraft:stone"},
        {pos: [13, 2, 12], state: "tl2:molecular_assembler{powered:true}", nbt: {id: "tl2:molecular_assembler", inv: {item0: {}, item1: {}, item10: {}, item2: {}, item3: {}, item4: {}, item5: {}, item6: {}, item7: {}, item8: {}, item9: {}}, proxy: {p: 0}, visual: {}}},
        {pos: [13, 2, 15], state: "minecraft:stone"},
        {pos: [14, 2, 2], state: "tl2:crafting_accelerator{formed:true,powered:true}", nbt: {core: 0b, id: "tl2:crafting_unit", proxy: {p: 0}, visual: {}}},
        {pos: [14, 2, 4], state: "tl2:crafting_accelerator{formed:true,powered:true}", nbt: {core: 0b, id: "tl2:crafting_unit", proxy: {p: 0}, visual: {}}},
        {pos: [14, 2, 6], state: "tl2:crafting_accelerator{formed:true,powered:true}", nbt: {core: 0b, id: "tl2:crafting_unit", proxy: {p: 0}, visual: {}}},
        {pos: [14, 2, 9], state: "minecraft:ladder{facing:west,waterlogged:false}"},
        {pos: [14, 2, 15], state: "minecraft:stone"},
        {pos: [15, 2, 5], state: "minecraft:stone"},
        {pos: [15, 2, 6], state: "tl2:crafting_accelerator{formed:true,powered:true}", nbt: {core: 0b, id: "tl2:crafting_unit", proxy: {p: 0}, visual: {}}},
        {pos: [15, 2, 7], state: "minecraft:stone"},
        {pos: [15, 2, 8], state: "tl2:cable_bus{light_level:0,waterlogged:false}", nbt: {cable: {gn: {p: 0}, id: "tl2:blue_smart_dense_cable", visual: {channelsSouth: 6, channelsUp: 6, connections: ["up", "south"], missingChannel: 0b, powered: 1b}}, facadeWest: {Name: "minecraft:stone_bricks"}, hasRedstone: 2, id: "tl2:cable_bus", visual: {}}},
        {pos: [15, 2, 9], state: "tl2:cable_bus{light_level:0,waterlogged:false}", nbt: {cable: {gn: {p: 0}, id: "tl2:blue_smart_dense_cable", visual: {channelsNorth: 6, channelsSouth: 6, connections: ["north", "south"], missingChannel: 0b, powered: 1b}}, facadeWest: {Name: "minecraft:stone_bricks"}, hasRedstone: 2, id: "tl2:cable_bus", visual: {}}},
        {pos: [15, 2, 10], state: "tl2:cable_bus{light_level:0,waterlogged:false}", nbt: {cable: {gn: {p: 0}, id: "tl2:blue_smart_dense_cable", visual: {channelsNorth: 6, channelsSouth: 6, connections: ["north", "south"], missingChannel: 0b, powered: 1b}}, facadeWest: {Name: "minecraft:stone_bricks"}, hasRedstone: 2, id: "tl2:cable_bus", visual: {}}},
        {pos: [15, 2, 11], state: "tl2:cable_bus{light_level:0,waterlogged:false}", nbt: {cable: {gn: {p: 0}, id: "tl2:blue_smart_dense_cable", visual: {channelsNorth: 6, channelsSouth: 6, connections: ["north", "south"], missingChannel: 0b, powered: 1b}}, facadeWest: {Name: "minecraft:stone_bricks"}, hasRedstone: 2, id: "tl2:cable_bus", visual: {}}},
        {pos: [15, 2, 12], state: "tl2:cable_bus{light_level:0,waterlogged:false}", nbt: {cable: {gn: {p: 0}, id: "tl2:blue_smart_dense_cable", visual: {channelsNorth: 6, channelsUp: 6, connections: ["up", "north"], missingChannel: 0b, powered: 1b}}, facadeWest: {Name: "minecraft:stone_bricks"}, hasRedstone: 2, id: "tl2:cable_bus", visual: {}}},
        {pos: [15, 2, 13], state: "tl2:cable_bus{light_level:0,waterlogged:false}", nbt: {cable: {gn: {p: 0}, id: "tl2:white_smart_dense_cable", visual: {channelsDown: 16, channelsUp: 16, connections: ["down", "up"], missingChannel: 0b, powered: 1b}}, facadeWest: {Name: "minecraft:stone_bricks"}, hasRedstone: 2, id: "tl2:cable_bus", visual: {}}},
        {pos: [15, 2, 14], state: "minecraft:stone"},
        {pos: [15, 2, 15], state: "minecraft:stone"},
        {pos: [2, 3, 10], state: "minecraft:netherite_block"},
        {pos: [2, 3, 11], state: "minecraft:netherite_block"},
        {pos: [2, 3, 12], state: "minecraft:netherite_block"},
        {pos: [3, 3, 10], state: "minecraft:netherite_block"},
        {pos: [3, 3, 11], state: "minecraft:netherite_block"},
        {pos: [3, 3, 12], state: "minecraft:netherite_block"},
        {pos: [4, 3, 2], state: "tl2:cable_bus{light_level:0,waterlogged:false}", nbt: {cable: {gn: {p: 0}, id: "tl2:orange_smart_cable", visual: {channelsSouth: 1, connections: ["south"], missingChannel: 0b, powered: 1b}}, down: {access: "READ_WRITE", filter_on_extract: "YES", fuzzy_mode: "IGNORE_ALL", gn: {p: 0}, id: "tl2:storage_bus", priority: 0, storage_filter: "EXTRACTABLE_ONLY", visual: {missingChannel: 0b, powered: 1b}}, hasRedstone: 2, id: "tl2:cable_bus", visual: {}}},
        {pos: [4, 3, 3], state: "tl2:cable_bus{light_level:0,waterlogged:false}", nbt: {cable: {gn: {p: 0}, id: "tl2:orange_smart_cable", visual: {channelsNorth: 1, channelsSouth: 2, connections: ["north", "south"], missingChannel: 0b, powered: 1b}}, down: {access: "READ_WRITE", filter_on_extract: "YES", fuzzy_mode: "IGNORE_ALL", gn: {p: 0}, id: "tl2:storage_bus", priority: 0, storage_filter: "EXTRACTABLE_ONLY", visual: {missingChannel: 0b, powered: 1b}}, hasRedstone: 2, id: "tl2:cable_bus", visual: {}}},
        {pos: [4, 3, 4], state: "tl2:cable_bus{light_level:0,waterlogged:false}", nbt: {cable: {gn: {p: 0}, id: "tl2:orange_smart_cable", visual: {channelsNorth: 2, channelsSouth: 3, connections: ["north", "south"], missingChannel: 0b, powered: 1b}}, down: {access: "READ_WRITE", filter_on_extract: "YES", fuzzy_mode: "IGNORE_ALL", gn: {p: 0}, id: "tl2:storage_bus", priority: 0, storage_filter: "EXTRACTABLE_ONLY", visual: {missingChannel: 0b, powered: 1b}}, hasRedstone: 2, id: "tl2:cable_bus", visual: {}}},
        {pos: [4, 3, 5], state: "tl2:cable_bus{light_level:0,waterlogged:false}", nbt: {cable: {gn: {p: 0}, id: "tl2:orange_smart_cable", visual: {channelsNorth: 3, channelsSouth: 4, connections: ["north", "south"], missingChannel: 0b, powered: 1b}}, down: {access: "READ_WRITE", filter_on_extract: "YES", fuzzy_mode: "IGNORE_ALL", gn: {p: 0}, id: "tl2:storage_bus", priority: 0, storage_filter: "EXTRACTABLE_ONLY", visual: {missingChannel: 0b, powered: 1b}}, hasRedstone: 2, id: "tl2:cable_bus", visual: {}}},
        {pos: [4, 3, 6], state: "tl2:cable_bus{light_level:0,waterlogged:false}", nbt: {cable: {gn: {p: 0}, id: "tl2:orange_smart_cable", visual: {channelsEast: 6, channelsNorth: 4, channelsSouth: 1, connections: ["north", "south", "east"], missingChannel: 0b, powered: 1b}}, down: {access: "READ_WRITE", filter_on_extract: "YES", fuzzy_mode: "IGNORE_ALL", gn: {p: 0}, id: "tl2:storage_bus", priority: 0, storage_filter: "EXTRACTABLE_ONLY", visual: {missingChannel: 0b, powered: 1b}}, hasRedstone: 2, id: "tl2:cable_bus", visual: {}}},
        {pos: [4, 3, 7], state: "tl2:cable_bus{light_level:0,waterlogged:false}", nbt: {cable: {gn: {p: 0}, id: "tl2:orange_smart_cable", visual: {channelsNorth: 1, connections: ["north"], missingChannel: 0b, powered: 1b}}, down: {access: "READ_WRITE", filter_on_extract: "YES", fuzzy_mode: "IGNORE_ALL", gn: {p: 0}, id: "tl2:storage_bus", priority: 0, storage_filter: "EXTRACTABLE_ONLY", visual: {missingChannel: 0b, powered: 1b}}, hasRedstone: 2, id: "tl2:cable_bus", visual: {}}},
        {pos: [5, 3, 6], state: "tl2:controller{state:online,type:block}", nbt: {id: "tl2:controller", internalCurrentPower: 0.0d, proxy: {p: 0}, visual: {}}},
        {pos: [5, 3, 11], state: "tl2:molecular_assembler{powered:true}", nbt: {id: "tl2:molecular_assembler", inv: {item0: {}, item1: {}, item10: {}, item2: {}, item3: {}, item4: {}, item5: {}, item6: {}, item7: {}, item8: {}, item9: {}}, proxy: {p: 0}, visual: {}}},
        {pos: [6, 3, 7], state: "tl2:cable_bus{light_level:0,waterlogged:false}", nbt: {cable: {gn: {p: 0}, id: "tl2:blue_smart_cable", visual: {channelsDown: 1, channelsUp: 1, connections: ["down", "up"], missingChannel: 0b, powered: 1b}}, hasRedstone: 2, id: "tl2:cable_bus", visual: {}}},
        {pos: [6, 3, 10], state: "tl2:molecular_assembler{powered:true}", nbt: {id: "tl2:molecular_assembler", inv: {item0: {}, item1: {}, item10: {}, item2: {}, item3: {}, item4: {}, item5: {}, item6: {}, item7: {}, item8: {}, item9: {}}, proxy: {p: 0}, visual: {}}},
        {pos: [6, 3, 11], state: "tl2:pattern_provider{push_direction:all}", nbt: {blocking_mode: "NO", id: "tl2:pattern_provider", lock_crafting_mode: "NONE", pattern_access_terminal: "YES", priority: 0, proxy: {p: 0}, returnInv: [], sendList: [], visual: {}}},
        {pos: [6, 3, 12], state: "tl2:molecular_assembler{powered:true}", nbt: {id: "tl2:molecular_assembler", inv: {item0: {}, item1: {}, item10: {}, item2: {}, item3: {}, item4: {}, item5: {}, item6: {}, item7: {}, item8: {}, item9: {}}, proxy: {p: 0}, visual: {}}},
        {pos: [7, 3, 11], state: "tl2:molecular_assembler{powered:true}", nbt: {id: "tl2:molecular_assembler", inv: {item0: {}, item1: {}, item10: {}, item2: {}, item3: {}, item4: {}, item5: {}, item6: {}, item7: {}, item8: {}, item9: {}}, proxy: {p: 0}, visual: {}}},
        {pos: [7, 3, 12], state: "tl2:pattern_provider{push_direction:all}", nbt: {blocking_mode: "NO", id: "tl2:pattern_provider", lock_crafting_mode: "NONE", pattern_access_terminal: "YES", priority: 0, proxy: {p: 0}, returnInv: [], sendList: [], visual: {}}},
        {pos: [7, 3, 13], state: "tl2:molecular_assembler{powered:true}", nbt: {id: "tl2:molecular_assembler", inv: {item0: {}, item1: {}, item10: {}, item2: {}, item3: {}, item4: {}, item5: {}, item6: {}, item7: {}, item8: {}, item9: {}}, proxy: {p: 0}, visual: {}}},
        {pos: [8, 3, 4], state: "tl2:growth_accelerator{facing:south,powered:true}", nbt: {id: "tl2:growth_accelerator", proxy: {p: 0}, visual: {}}},
        {pos: [8, 3, 5], state: "tl2:cable_bus{light_level:0,waterlogged:false}", nbt: {cable: {gn: {p: 0}, id: "tl2:orange_smart_cable", visual: {channelsDown: 4, channelsNorth: 4, connections: ["down", "north"], missingChannel: 0b, powered: 1b}}, hasRedstone: 2, id: "tl2:cable_bus", south: {access: "READ_WRITE", config: [{"#": 0L, "#t": "tl2:i", id: "tl2:certus_quartz_crystal"}], filter_on_extract: "YES", fuzzy_mode: "IGNORE_ALL", gn: {p: 0}, id: "tl2:storage_bus", priority: 0, storage_filter: "EXTRACTABLE_ONLY", visual: {missingChannel: 0b, powered: 1b}}, up: {gn: {p: 0}, id: "tl2:quartz_fiber", outer: {p: 0}, visual: {missingChannel: 0b, powered: 1b}}, visual: {}}},
        {pos: [8, 3, 6], state: "minecraft:barrel{facing:west,open:false}", nbt: {Items: [{Count: 64b, Slot: 0b, id: "tl2:certus_quartz_crystal"}, {Count: 64b, Slot: 1b, id: "tl2:certus_quartz_crystal"}, {Count: 64b, Slot: 2b, id: "tl2:certus_quartz_crystal"}, {Count: 64b, Slot: 3b, id: "tl2:certus_quartz_crystal"}, {Count: 64b, Slot: 4b, id: "tl2:certus_quartz_crystal"}, {Count: 64b, Slot: 5b, id: "tl2:certus_quartz_crystal"}, {Count: 64b, Slot: 6b, id: "tl2:certus_quartz_crystal"}, {Count: 64b, Slot: 7b, id: "tl2:certus_quartz_crystal"}, {Count: 64b, Slot: 8b, id: "tl2:certus_quartz_crystal"}, {Count: 64b, Slot: 9b, id: "tl2:certus_quartz_crystal"}, {Count: 64b, Slot: 10b, id: "tl2:certus_quartz_crystal"}, {Count: 64b, Slot: 11b, id: "tl2:certus_quartz_crystal"}, {Count: 64b, Slot: 12b, id: "tl2:certus_quartz_crystal"}, {Count: 64b, Slot: 13b, id: "tl2:certus_quartz_crystal"}, {Count: 64b, Slot: 14b, id: "tl2:certus_quartz_crystal"}, {Count: 64b, Slot: 15b, id: "tl2:certus_quartz_crystal"}, {Count: 64b, Slot: 16b, id: "tl2:certus_quartz_crystal"}, {Count: 36b, Slot: 17b, id: "tl2:certus_quartz_crystal"}, {Count: 23b, Slot: 23b, id: "tl2:certus_quartz_crystal"}], id: "minecraft:barrel"}},
        {pos: [8, 3, 12], state: "tl2:molecular_assembler{powered:true}", nbt: {id: "tl2:molecular_assembler", inv: {item0: {}, item1: {}, item10: {}, item2: {}, item3: {}, item4: {}, item5: {}, item6: {}, item7: {}, item8: {}, item9: {}}, proxy: {p: 0}, visual: {}}},
        {pos: [9, 3, 15], state: "minecraft:stone"},
        {pos: [10, 3, 12], state: "tl2:molecular_assembler{powered:true}", nbt: {id: "tl2:molecular_assembler", inv: {item0: {}, item1: {}, item10: {}, item2: {}, item3: {}, item4: {}, item5: {}, item6: {}, item7: {}, item8: {}, item9: {}}, proxy: {p: 0}, visual: {}}},
        {pos: [10, 3, 15], state: "minecraft:stone"},
        {pos: [11, 3, 3], state: "tl2:cable_bus{light_level:0,waterlogged:false}", nbt: {cable: {gn: {p: 0}, id: "tl2:orange_smart_cable", visual: {channelsSouth: 2, connections: ["south"], missingChannel: 0b, powered: 1b}}, down: {gn: {p: 0}, id: "tl2:annihilation_plane", visual: {missingChannel: 0b, powered: 1b}}, hasRedstone: 2, id: "tl2:cable_bus", visual: {}}},
        {pos: [11, 3, 4], state: "tl2:cable_bus{light_level:0,waterlogged:false}", nbt: {cable: {gn: {p: 0}, id: "tl2:orange_smart_cable", visual: {channelsDown: 2, channelsNorth: 2, connections: ["down", "north"], missingChannel: 0b, powered: 1b}}, hasRedstone: 2, id: "tl2:cable_bus", visual: {}}},
        {pos: [11, 3, 5], state: "tl2:cable_bus{light_level:0,waterlogged:false}", nbt: {cable: {gn: {p: 0}, id: "tl2:blue_smart_cable", visual: {channelsDown: 1, channelsUp: 1, connections: ["down", "up"], missingChannel: 0b, powered: 1b}}, hasRedstone: 2, id: "tl2:cable_bus", visual: {}}},
        {pos: [11, 3, 11], state: "tl2:molecular_assembler{powered:true}", nbt: {id: "tl2:molecular_assembler", inv: {item0: {}, item1: {}, item10: {}, item2: {}, item3: {}, item4: {}, item5: {}, item6: {}, item7: {}, item8: {}, item9: {}}, proxy: {p: 0}, visual: {}}},
        {pos: [11, 3, 12], state: "tl2:pattern_provider{push_direction:all}", nbt: {blocking_mode: "NO", id: "tl2:pattern_provider", lock_crafting_mode: "NONE", pattern_access_terminal: "YES", priority: 0, proxy: {p: 0}, returnInv: [], sendList: [], visual: {}}},
        {pos: [11, 3, 13], state: "tl2:molecular_assembler{powered:true}", nbt: {id: "tl2:molecular_assembler", inv: {item0: {}, item1: {}, item10: {}, item2: {}, item3: {}, item4: {}, item5: {}, item6: {}, item7: {}, item8: {}, item9: {}}, proxy: {p: 0}, visual: {}}},
        {pos: [11, 3, 15], state: "minecraft:stone"},
        {pos: [12, 3, 10], state: "tl2:molecular_assembler{powered:true}", nbt: {id: "tl2:molecular_assembler", inv: {item0: {}, item1: {}, item10: {}, item2: {}, item3: {}, item4: {}, item5: {}, item6: {}, item7: {}, item8: {}, item9: {}}, proxy: {p: 0}, visual: {}}},
        {pos: [12, 3, 11], state: "tl2:pattern_provider{push_direction:all}", nbt: {blocking_mode: "NO", id: "tl2:pattern_provider", lock_crafting_mode: "NONE", pattern_access_terminal: "YES", priority: 0, proxy: {p: 0}, returnInv: [], sendList: [], visual: {}}},
        {pos: [12, 3, 12], state: "tl2:molecular_assembler{powered:true}", nbt: {id: "tl2:molecular_assembler", inv: {item0: {}, item1: {}, item10: {}, item2: {}, item3: {}, item4: {}, item5: {}, item6: {}, item7: {}, item8: {}, item9: {}}, proxy: {p: 0}, visual: {}}},
        {pos: [12, 3, 15], state: "minecraft:stone"},
        {pos: [13, 3, 11], state: "tl2:molecular_assembler{powered:true}", nbt: {id: "tl2:molecular_assembler", inv: {item0: {}, item1: {}, item10: {}, item2: {}, item3: {}, item4: {}, item5: {}, item6: {}, item7: {}, item8: {}, item9: {}}, proxy: {p: 0}, visual: {}}},
        {pos: [13, 3, 15], state: "minecraft:stone"},
        {pos: [14, 3, 2], state: "tl2:4k_crafting_storage{formed:true,powered:true}", nbt: {core: 0b, id: "tl2:crafting_storage", proxy: {p: 0}, visual: {}}},
        {pos: [14, 3, 3], state: "tl2:cable_bus{light_level:0,waterlogged:false}", nbt: {cable: {gn: {p: 0}, id: "tl2:blue_smart_cable", visual: {channelsNorth: 1, channelsSouth: 1, connections: ["north", "south"], missingChannel: 0b, powered: 1b}}, hasRedstone: 2, id: "tl2:cable_bus", visual: {}}},
        {pos: [14, 3, 4], state: "tl2:4k_crafting_storage{formed:true,powered:true}", nbt: {core: 0b, id: "tl2:crafting_storage", proxy: {p: 0}, visual: {}}},
        {pos: [14, 3, 5], state: "tl2:cable_bus{light_level:0,waterlogged:false}", nbt: {cable: {gn: {p: 0}, id: "tl2:blue_smart_cable", visual: {channelsNorth: 2, channelsSouth: 2, connections: ["north", "south"], missingChannel: 0b, powered: 1b}}, hasRedstone: 2, id: "tl2:cable_bus", visual: {}}},
        {pos: [14, 3, 6], state: "tl2:64k_crafting_storage{formed:true,powered:true}", nbt: {core: 0b, id: "tl2:crafting_storage", proxy: {p: 0}, visual: {}}},
        {pos: [14, 3, 9], state: "minecraft:ladder{facing:west,waterlogged:false}"},
        {pos: [14, 3, 15], state: "minecraft:stone"},
        {pos: [15, 3, 6], state: "tl2:crafting_accelerator{formed:true,powered:true}", nbt: {core: 0b, id: "tl2:crafting_unit", proxy: {p: 0}, visual: {}}},
        {pos: [15, 3, 7], state: "minecraft:stone"},
        {pos: [15, 3, 8], state: "tl2:cable_bus{light_level:0,waterlogged:false}", nbt: {cable: {gn: {p: 0}, id: "tl2:blue_smart_dense_cable", visual: {channelsDown: 6, channelsUp: 6, connections: ["down", "up"], missingChannel: 0b, powered: 1b}}, facadeWest: {Name: "minecraft:stone_bricks"}, hasRedstone: 2, id: "tl2:cable_bus", visual: {}}},
        {pos: [15, 3, 9], state: "minecraft:stone"},
        {pos: [15, 3, 10], state: "minecraft:stone"},
        {pos: [15, 3, 11], state: "minecraft:stone"},
        {pos: [15, 3, 12], state: "tl2:cable_bus{light_level:0,waterlogged:false}", nbt: {cable: {gn: {p: 0}, id: "tl2:blue_smart_dense_cable", visual: {channelsDown: 6, channelsUp: 6, connections: ["down", "up"], missingChannel: 0b, powered: 1b}}, facadeWest: {Name: "minecraft:stone_bricks"}, hasRedstone: 2, id: "tl2:cable_bus", visual: {}}},
        {pos: [15, 3, 13], state: "tl2:cable_bus{light_level:0,waterlogged:false}", nbt: {cable: {gn: {p: 0}, id: "tl2:white_smart_dense_cable", visual: {channelsDown: 16, channelsUp: 16, connections: ["down", "up"], missingChannel: 0b, powered: 1b}}, facadeWest: {Name: "minecraft:stone_bricks"}, hasRedstone: 2, id: "tl2:cable_bus", visual: {}}},
        {pos: [15, 3, 14], state: "minecraft:stone"},
        {pos: [15, 3, 15], state: "minecraft:stone"},
        {pos: [4, 4, 8], state: "tl2:cable_bus{light_level:0,waterlogged:false}", nbt: {cable: {gn: {p: 0}, id: "tl2:blue_smart_dense_cable", visual: {channelsEast: 0, connections: ["east"], missingChannel: 0b, powered: 1b}}, hasRedstone: 2, id: "tl2:cable_bus", visual: {}}},
        {pos: [5, 4, 8], state: "tl2:cable_bus{light_level:0,waterlogged:false}", nbt: {cable: {gn: {p: 0}, id: "tl2:blue_smart_dense_cable", visual: {channelsEast: 0, channelsWest: 0, connections: ["west", "east"], missingChannel: 0b, powered: 1b}}, hasRedstone: 2, id: "tl2:cable_bus", visual: {}}},
        {pos: [5, 4, 12], state: "tl2:molecular_assembler{powered:true}", nbt: {id: "tl2:molecular_assembler", inv: {item0: {}, item1: {}, item10: {}, item2: {}, item3: {}, item4: {}, item5: {}, item6: {}, item7: {}, item8: {}, item9: {}}, proxy: {p: 0}, visual: {}}},
        {pos: [6, 4, 7], state: "tl2:cable_bus{light_level:0,waterlogged:false}", nbt: {cable: {gn: {p: 0}, id: "tl2:blue_smart_cable", visual: {channelsDown: 1, channelsSouth: 1, connections: ["down", "south"], missingChannel: 0b, powered: 1b}}, hasRedstone: 2, id: "tl2:cable_bus", visual: {}}},
        {pos: [6, 4, 8], state: "tl2:cable_bus{light_level:0,waterlogged:false}", nbt: {cable: {gn: {p: 0}, id: "tl2:blue_smart_dense_cable", visual: {channelsEast: 1, channelsNorth: 1, channelsWest: 0, connections: ["north", "west", "east"], missingChannel: 0b, powered: 1b}}, hasRedstone: 2, id: "tl2:cable_bus", visual: {}}},
        {pos: [6, 4, 11], state: "tl2:molecular_assembler{powered:true}", nbt: {id: "tl2:molecular_assembler", inv: {item0: {}, item1: {}, item10: {}, item2: {}, item3: {}, item4: {}, item5: {}, item6: {}, item7: {}, item8: {}, item9: {}}, proxy: {p: 0}, visual: {}}},
        {pos: [6, 4, 12], state: "tl2:pattern_provider{push_direction:all}", nbt: {blocking_mode: "NO", id: "tl2:pattern_provider", lock_crafting_mode: "NONE", pattern_access_terminal: "YES", priority: 0, proxy: {p: 0}, returnInv: [], sendList: [], visual: {}}},
        {pos: [6, 4, 13], state: "tl2:molecular_assembler{powered:true}", nbt: {id: "tl2:molecular_assembler", inv: {item0: {}, item1: {}, item10: {}, item2: {}, item3: {}, item4: {}, item5: {}, item6: {}, item7: {}, item8: {}, item9: {}}, proxy: {p: 0}, visual: {}}},
        {pos: [7, 4, 8], state: "tl2:cable_bus{light_level:0,waterlogged:false}", nbt: {cable: {gn: {p: 0}, id: "tl2:blue_smart_dense_cable", visual: {channelsEast: 1, channelsWest: 1, connections: ["west", "east"], missingChannel: 0b, powered: 1b}}, hasRedstone: 2, id: "tl2:cable_bus", visual: {}}},
        {pos: [7, 4, 10], state: "tl2:molecular_assembler{powered:true}", nbt: {id: "tl2:molecular_assembler", inv: {item0: {}, item1: {}, item10: {}, item2: {}, item3: {}, item4: {}, item5: {}, item6: {}, item7: {}, item8: {}, item9: {}}, proxy: {p: 0}, visual: {}}},
        {pos: [7, 4, 11], state: "tl2:pattern_provider{push_direction:all}", nbt: {blocking_mode: "NO", id: "tl2:pattern_provider", lock_crafting_mode: "NONE", pattern_access_terminal: "YES", priority: 0, proxy: {p: 0}, returnInv: [], sendList: [], visual: {}}},
        {pos: [7, 4, 12], state: "tl2:molecular_assembler{powered:true}", nbt: {id: "tl2:molecular_assembler", inv: {item0: {}, item1: {}, item10: {}, item2: {}, item3: {}, item4: {}, item5: {}, item6: {}, item7: {}, item8: {}, item9: {}}, proxy: {p: 0}, visual: {}}},
        {pos: [8, 4, 5], state: "tl2:cable_bus{light_level:0,waterlogged:false}", nbt: {cable: {gn: {p: 0}, id: "tl2:blue_smart_cable", visual: {channelsDown: 0, channelsSouth: 0, connections: ["down", "south"], missingChannel: 0b, powered: 1b}}, hasRedstone: 2, id: "tl2:cable_bus", visual: {}}},
        {pos: [8, 4, 6], state: "tl2:cable_bus{light_level:0,waterlogged:false}", nbt: {cable: {gn: {p: 0}, id: "tl2:blue_smart_cable", visual: {channelsNorth: 0, channelsSouth: 1, connections: ["north", "south"], missingChannel: 0b, powered: 1b}}, down: {access: "READ_WRITE", config: [{"#": 0L, "#t": "tl2:i", id: "tl2:certus_quartz_crystal"}], filter_on_extract: "YES", fuzzy_mode: "IGNORE_ALL", gn: {p: 0}, id: "tl2:storage_bus", priority: 1, storage_filter: "EXTRACTABLE_ONLY", visual: {missingChannel: 0b, powered: 1b}}, hasRedstone: 2, id: "tl2:cable_bus", visual: {}}},
        {pos: [8, 4, 7], state: "tl2:cable_bus{light_level:0,waterlogged:false}", nbt: {cable: {gn: {p: 0}, id: "tl2:blue_smart_cable", visual: {channelsNorth: 1, channelsSouth: 1, connections: ["north", "south"], missingChannel: 0b, powered: 1b}}, hasRedstone: 2, id: "tl2:cable_bus", visual: {}}},
        {pos: [8, 4, 8], state: "tl2:cable_bus{light_level:0,waterlogged:false}", nbt: {cable: {gn: {p: 0}, id: "tl2:blue_smart_dense_cable", visual: {channelsEast: 2, channelsNorth: 1, channelsWest: 1, connections: ["north", "west", "east"], missingChannel: 0b, powered: 1b}}, hasRedstone: 2, id: "tl2:cable_bus", visual: {}}},
        {pos: [8, 4, 11], state: "tl2:molecular_assembler{powered:true}", nbt: {id: "tl2:molecular_assembler", inv: {item0: {}, item1: {}, item10: {}, item2: {}, item3: {}, item4: {}, item5: {}, item6: {}, item7: {}, item8: {}, item9: {}}, proxy: {p: 0}, visual: {}}},
        {pos: [8, 4, 15], state: "minecraft:stone"},
        {pos: [9, 4, 8], state: "tl2:cable_bus{light_level:0,waterlogged:false}", nbt: {cable: {gn: {p: 0}, id: "tl2:blue_smart_dense_cable", visual: {channelsEast: 2, channelsWest: 2, connections: ["west", "east"], missingChannel: 0b, powered: 1b}}, hasRedstone: 2, id: "tl2:cable_bus", visual: {}}},
        {pos: [9, 4, 15], state: "minecraft:stone"},
        {pos: [10, 4, 8], state: "tl2:cable_bus{light_level:0,waterlogged:false}", nbt: {cable: {gn: {p: 0}, id: "tl2:blue_smart_dense_cable", visual: {channelsEast: 2, channelsWest: 2, connections: ["west", "east"], missingChannel: 0b, powered: 1b}}, hasRedstone: 2, id: "tl2:cable_bus", visual: {}}},
        {pos: [10, 4, 11], state: "tl2:molecular_assembler{powered:true}", nbt: {id: "tl2:molecular_assembler", inv: {item0: {}, item1: {}, item10: {}, item2: {}, item3: {}, item4: {}, item5: {}, item6: {}, item7: {}, item8: {}, item9: {}}, proxy: {p: 0}, visual: {}}},
        {pos: [10, 4, 15], state: "minecraft:stone"},
        {pos: [11, 4, 5], state: "tl2:cable_bus{light_level:0,waterlogged:false}", nbt: {cable: {gn: {p: 0}, id: "tl2:blue_smart_cable", visual: {channelsDown: 1, channelsSouth: 1, connections: ["down", "south"], missingChannel: 0b, powered: 1b}}, hasRedstone: 2, id: "tl2:cable_bus", visual: {}}},
        {pos: [11, 4, 6], state: "tl2:cable_bus{light_level:0,waterlogged:false}", nbt: {cable: {gn: {p: 0}, id: "tl2:blue_smart_cable", visual: {channelsNorth: 1, channelsSouth: 1, connections: ["north", "south"], missingChannel: 0b, powered: 1b}}, hasRedstone: 2, id: "tl2:cable_bus", visual: {}}},
        {pos: [11, 4, 7], state: "tl2:cable_bus{light_level:0,waterlogged:false}", nbt: {cable: {gn: {p: 0}, id: "tl2:blue_smart_cable", visual: {channelsNorth: 1, channelsSouth: 1, connections: ["north", "south"], missingChannel: 0b, powered: 1b}}, hasRedstone: 2, id: "tl2:cable_bus", visual: {}}},
        {pos: [11, 4, 8], state: "tl2:cable_bus{light_level:0,waterlogged:false}", nbt: {cable: {gn: {p: 0}, id: "tl2:blue_smart_dense_cable", visual: {channelsEast: 3, channelsNorth: 1, channelsWest: 2, connections: ["north", "west", "east"], missingChannel: 0b, powered: 1b}}, hasRedstone: 2, id: "tl2:cable_bus", visual: {}}},
        {pos: [11, 4, 10], state: "tl2:molecular_assembler{powered:true}", nbt: {id: "tl2:molecular_assembler", inv: {item0: {}, item1: {}, item10: {}, item2: {}, item3: {}, item4: {}, item5: {}, item6: {}, item7: {}, item8: {}, item9: {}}, proxy: {p: 0}, visual: {}}},
        {pos: [11, 4, 11], state: "tl2:pattern_provider{push_direction:all}", nbt: {blocking_mode: "NO", id: "tl2:pattern_provider", lock_crafting_mode: "NONE", pattern_access_terminal: "YES", priority: 0, proxy: {p: 0}, returnInv: [], sendList: [], visual: {}}},
        {pos: [11, 4, 12], state: "tl2:molecular_assembler{powered:true}", nbt: {id: "tl2:molecular_assembler", inv: {item0: {}, item1: {}, item10: {}, item2: {}, item3: {}, item4: {}, item5: {}, item6: {}, item7: {}, item8: {}, item9: {}}, proxy: {p: 0}, visual: {}}},
        {pos: [11, 4, 15], state: "minecraft:stone"},
        {pos: [12, 4, 8], state: "tl2:cable_bus{light_level:0,waterlogged:false}", nbt: {cable: {gn: {p: 0}, id: "tl2:blue_smart_dense_cable", visual: {channelsEast: 3, channelsWest: 3, connections: ["west", "east"], missingChannel: 0b, powered: 1b}}, hasRedstone: 2, id: "tl2:cable_bus", visual: {}}},
        {pos: [12, 4, 11], state: "tl2:molecular_assembler{powered:true}", nbt: {id: "tl2:molecular_assembler", inv: {item0: {}, item1: {}, item10: {}, item2: {}, item3: {}, item4: {}, item5: {}, item6: {}, item7: {}, item8: {}, item9: {}}, proxy: {p: 0}, visual: {}}},
        {pos: [12, 4, 12], state: "tl2:pattern_provider{push_direction:all}", nbt: {blocking_mode: "NO", id: "tl2:pattern_provider", lock_crafting_mode: "NONE", pattern_access_terminal: "YES", priority: 0, proxy: {p: 0}, returnInv: [], sendList: [], visual: {}}},
        {pos: [12, 4, 13], state: "tl2:molecular_assembler{powered:true}", nbt: {id: "tl2:molecular_assembler", inv: {item0: {}, item1: {}, item10: {}, item2: {}, item3: {}, item4: {}, item5: {}, item6: {}, item7: {}, item8: {}, item9: {}}, proxy: {p: 0}, visual: {}}},
        {pos: [12, 4, 15], state: "minecraft:stone"},
        {pos: [13, 4, 8], state: "tl2:cable_bus{light_level:0,waterlogged:false}", nbt: {cable: {gn: {p: 0}, id: "tl2:blue_smart_dense_cable", visual: {channelsEast: 3, channelsWest: 3, connections: ["west", "east"], missingChannel: 0b, powered: 1b}}, hasRedstone: 2, id: "tl2:cable_bus", visual: {}}},
        {pos: [13, 4, 12], state: "tl2:molecular_assembler{powered:true}", nbt: {id: "tl2:molecular_assembler", inv: {item0: {}, item1: {}, item10: {}, item2: {}, item3: {}, item4: {}, item5: {}, item6: {}, item7: {}, item8: {}, item9: {}}, proxy: {p: 0}, visual: {}}},
        {pos: [13, 4, 15], state: "minecraft:stone"},
        {pos: [14, 4, 2], state: "tl2:crafting_monitor{facing:west,formed:true,powered:true,spin:0}", nbt: {core: 0b, id: "tl2:crafting_monitor", paintedColor: 11b, proxy: {p: 0}, visual: {}}},
        {pos: [14, 4, 4], state: "tl2:crafting_monitor{facing:west,formed:true,powered:true,spin:0}", nbt: {core: 0b, id: "tl2:crafting_monitor", paintedColor: 11b, proxy: {p: 0}, visual: {}}},
        {pos: [14, 4, 6], state: "tl2:crafting_monitor{facing:west,formed:true,powered:true,spin:0}", nbt: {core: 0b, id: "tl2:crafting_monitor", paintedColor: 11b, proxy: {p: 0}, visual: {}}},
        {pos: [14, 4, 7], state: "tl2:cable_bus{light_level:0,waterlogged:false}", nbt: {cable: {gn: {p: 0}, id: "tl2:blue_smart_cable", visual: {channelsNorth: 3, channelsSouth: 3, connections: ["north", "south"], missingChannel: 0b, powered: 1b}}, hasRedstone: 2, id: "tl2:cable_bus", visual: {}}},
        {pos: [14, 4, 8], state: "tl2:cable_bus{light_level:0,waterlogged:false}", nbt: {cable: {gn: {p: 0}, id: "tl2:blue_smart_dense_cable", visual: {channelsEast: 6, channelsNorth: 3, channelsWest: 3, connections: ["north", "west", "east"], missingChannel: 0b, powered: 1b}}, hasRedstone: 2, id: "tl2:cable_bus", visual: {}}},
        {pos: [14, 4, 9], state: "minecraft:ladder{facing:west,waterlogged:false}"},
        {pos: [14, 4, 15], state: "minecraft:stone"},
        {pos: [15, 4, 6], state: "tl2:crafting_accelerator{formed:true,powered:true}", nbt: {core: 0b, id: "tl2:crafting_unit", proxy: {p: 0}, visual: {}}},
        {pos: [15, 4, 7], state: "minecraft:stone"},
        {pos: [15, 4, 8], state: "tl2:cable_bus{light_level:0,waterlogged:false}", nbt: {cable: {gn: {p: 0}, id: "tl2:blue_smart_dense_cable", visual: {channelsDown: 6, channelsWest: 6, connections: ["down", "west"], missingChannel: 0b, powered: 1b}}, facadeWest: {Name: "minecraft:stone_bricks"}, hasRedstone: 2, id: "tl2:cable_bus", visual: {}}},
        {pos: [15, 4, 9], state: "minecraft:stone"},
        {pos: [15, 4, 10], state: "minecraft:stone"},
        {pos: [15, 4, 11], state: "minecraft:stone"},
        {pos: [15, 4, 12], state: "tl2:cable_bus{light_level:0,waterlogged:false}", nbt: {cable: {gn: {p: 0}, id: "tl2:blue_smart_dense_cable", visual: {channelsDown: 6, channelsUp: 6, connections: ["down", "up"], missingChannel: 0b, powered: 1b}}, facadeWest: {Name: "minecraft:stone_bricks"}, hasRedstone: 2, id: "tl2:cable_bus", visual: {}}},
        {pos: [15, 4, 13], state: "tl2:cable_bus{light_level:0,waterlogged:false}", nbt: {cable: {gn: {p: 0}, id: "tl2:white_smart_dense_cable", visual: {channelsDown: 16, channelsUp: 16, connections: ["down", "up"], missingChannel: 0b, powered: 1b}}, facadeWest: {Name: "minecraft:stone_bricks"}, hasRedstone: 2, id: "tl2:cable_bus", visual: {}}},
        {pos: [15, 4, 14], state: "minecraft:stone"},
        {pos: [15, 4, 15], state: "minecraft:stone"},
        {pos: [5, 5, 11], state: "tl2:molecular_assembler{powered:true}", nbt: {id: "tl2:molecular_assembler", inv: {item0: {}, item1: {}, item10: {}, item2: {}, item3: {}, item4: {}, item5: {}, item6: {}, item7: {}, item8: {}, item9: {}}, proxy: {p: 0}, visual: {}}},
        {pos: [6, 5, 10], state: "tl2:molecular_assembler{powered:true}", nbt: {id: "tl2:molecular_assembler", inv: {item0: {}, item1: {}, item10: {}, item2: {}, item3: {}, item4: {}, item5: {}, item6: {}, item7: {}, item8: {}, item9: {}}, proxy: {p: 0}, visual: {}}},
        {pos: [6, 5, 11], state: "tl2:pattern_provider{push_direction:all}", nbt: {blocking_mode: "NO", id: "tl2:pattern_provider", lock_crafting_mode: "NONE", pattern_access_terminal: "YES", priority: 0, proxy: {p: 0}, returnInv: [], sendList: [], visual: {}}},
        {pos: [6, 5, 12], state: "tl2:molecular_assembler{powered:true}", nbt: {id: "tl2:molecular_assembler", inv: {item0: {}, item1: {}, item10: {}, item2: {}, item3: {}, item4: {}, item5: {}, item6: {}, item7: {}, item8: {}, item9: {}}, proxy: {p: 0}, visual: {}}},
        {pos: [7, 5, 11], state: "tl2:molecular_assembler{powered:true}", nbt: {id: "tl2:molecular_assembler", inv: {item0: {}, item1: {}, item10: {}, item2: {}, item3: {}, item4: {}, item5: {}, item6: {}, item7: {}, item8: {}, item9: {}}, proxy: {p: 0}, visual: {}}},
        {pos: [7, 5, 12], state: "tl2:pattern_provider{push_direction:all}", nbt: {blocking_mode: "NO", id: "tl2:pattern_provider", lock_crafting_mode: "NONE", pattern_access_terminal: "YES", priority: 0, proxy: {p: 0}, returnInv: [], sendList: [], visual: {}}},
        {pos: [7, 5, 13], state: "tl2:molecular_assembler{powered:true}", nbt: {id: "tl2:molecular_assembler", inv: {item0: {}, item1: {}, item10: {}, item2: {}, item3: {}, item4: {}, item5: {}, item6: {}, item7: {}, item8: {}, item9: {}}, proxy: {p: 0}, visual: {}}},
        {pos: [8, 5, 12], state: "tl2:molecular_assembler{powered:true}", nbt: {id: "tl2:molecular_assembler", inv: {item0: {}, item1: {}, item10: {}, item2: {}, item3: {}, item4: {}, item5: {}, item6: {}, item7: {}, item8: {}, item9: {}}, proxy: {p: 0}, visual: {}}},
        {pos: [8, 5, 15], state: "minecraft:stone"},
        {pos: [9, 5, 15], state: "minecraft:stone"},
        {pos: [10, 5, 12], state: "tl2:molecular_assembler{powered:true}", nbt: {id: "tl2:molecular_assembler", inv: {item0: {}, item1: {}, item10: {}, item2: {}, item3: {}, item4: {}, item5: {}, item6: {}, item7: {}, item8: {}, item9: {}}, proxy: {p: 0}, visual: {}}},
        {pos: [10, 5, 15], state: "minecraft:stone"},
        {pos: [11, 5, 11], state: "tl2:molecular_assembler{powered:true}", nbt: {id: "tl2:molecular_assembler", inv: {item0: {}, item1: {}, item10: {}, item2: {}, item3: {}, item4: {}, item5: {}, item6: {}, item7: {}, item8: {}, item9: {}}, proxy: {p: 0}, visual: {}}},
        {pos: [11, 5, 12], state: "tl2:pattern_provider{push_direction:all}", nbt: {blocking_mode: "NO", id: "tl2:pattern_provider", lock_crafting_mode: "NONE", pattern_access_terminal: "YES", priority: 0, proxy: {p: 0}, returnInv: [], sendList: [], visual: {}}},
        {pos: [11, 5, 13], state: "tl2:molecular_assembler{powered:true}", nbt: {id: "tl2:molecular_assembler", inv: {item0: {}, item1: {}, item10: {}, item2: {}, item3: {}, item4: {}, item5: {}, item6: {}, item7: {}, item8: {}, item9: {}}, proxy: {p: 0}, visual: {}}},
        {pos: [11, 5, 15], state: "minecraft:stone"},
        {pos: [12, 5, 10], state: "tl2:molecular_assembler{powered:true}", nbt: {id: "tl2:molecular_assembler", inv: {item0: {}, item1: {}, item10: {}, item2: {}, item3: {}, item4: {}, item5: {}, item6: {}, item7: {}, item8: {}, item9: {}}, proxy: {p: 0}, visual: {}}},
        {pos: [12, 5, 11], state: "tl2:pattern_provider{push_direction:all}", nbt: {blocking_mode: "NO", id: "tl2:pattern_provider", lock_crafting_mode: "NONE", pattern_access_terminal: "YES", priority: 0, proxy: {p: 0}, returnInv: [], sendList: [], visual: {}}},
        {pos: [12, 5, 12], state: "tl2:molecular_assembler{powered:true}", nbt: {id: "tl2:molecular_assembler", inv: {item0: {}, item1: {}, item10: {}, item2: {}, item3: {}, item4: {}, item5: {}, item6: {}, item7: {}, item8: {}, item9: {}}, proxy: {p: 0}, visual: {}}},
        {pos: [12, 5, 15], state: "minecraft:stone"},
        {pos: [13, 5, 11], state: "tl2:molecular_assembler{powered:true}", nbt: {id: "tl2:molecular_assembler", inv: {item0: {}, item1: {}, item10: {}, item2: {}, item3: {}, item4: {}, item5: {}, item6: {}, item7: {}, item8: {}, item9: {}}, proxy: {p: 0}, visual: {}}},
        {pos: [13, 5, 15], state: "minecraft:stone"},
        {pos: [14, 5, 9], state: "minecraft:ladder{facing:west,waterlogged:false}"},
        {pos: [14, 5, 15], state: "minecraft:stone"},
        {pos: [15, 5, 9], state: "minecraft:stone"},
        {pos: [15, 5, 10], state: "minecraft:stone"},
        {pos: [15, 5, 11], state: "minecraft:stone"},
        {pos: [15, 5, 12], state: "tl2:cable_bus{light_level:0,waterlogged:false}", nbt: {cable: {gn: {p: 0}, id: "tl2:blue_smart_dense_cable", visual: {channelsDown: 6, channelsUp: 6, connections: ["down", "up"], missingChannel: 0b, powered: 1b}}, facadeWest: {Name: "tl2:quartz_glass"}, hasRedstone: 2, id: "tl2:cable_bus", visual: {}}},
        {pos: [15, 5, 13], state: "tl2:cable_bus{light_level:0,waterlogged:false}", nbt: {cable: {gn: {p: 0}, id: "tl2:white_smart_dense_cable", visual: {channelsDown: 16, channelsUp: 16, connections: ["down", "up"], missingChannel: 0b, powered: 1b}}, facadeWest: {Name: "tl2:quartz_glass"}, hasRedstone: 2, id: "tl2:cable_bus", visual: {}}},
        {pos: [15, 5, 14], state: "minecraft:stone"},
        {pos: [15, 5, 15], state: "minecraft:stone"},
        {pos: [6, 6, 11], state: "tl2:molecular_assembler{powered:true}", nbt: {id: "tl2:molecular_assembler", inv: {item0: {}, item1: {}, item10: {}, item2: {}, item3: {}, item4: {}, item5: {}, item6: {}, item7: {}, item8: {}, item9: {}}, proxy: {p: 0}, visual: {}}},
        {pos: [7, 6, 12], state: "tl2:molecular_assembler{powered:true}", nbt: {id: "tl2:molecular_assembler", inv: {item0: {}, item1: {}, item10: {}, item2: {}, item3: {}, item4: {}, item5: {}, item6: {}, item7: {}, item8: {}, item9: {}}, proxy: {p: 0}, visual: {}}},
        {pos: [8, 6, 15], state: "minecraft:stone"},
        {pos: [9, 6, 15], state: "minecraft:stone"},
        {pos: [10, 6, 15], state: "minecraft:stone"},
        {pos: [11, 6, 12], state: "tl2:molecular_assembler{powered:true}", nbt: {id: "tl2:molecular_assembler", inv: {item0: {}, item1: {}, item10: {}, item2: {}, item3: {}, item4: {}, item5: {}, item6: {}, item7: {}, item8: {}, item9: {}}, proxy: {p: 0}, visual: {}}},
        {pos: [11, 6, 15], state: "minecraft:stone"},
        {pos: [12, 6, 11], state: "tl2:molecular_assembler{powered:true}", nbt: {id: "tl2:molecular_assembler", inv: {item0: {}, item1: {}, item10: {}, item2: {}, item3: {}, item4: {}, item5: {}, item6: {}, item7: {}, item8: {}, item9: {}}, proxy: {p: 0}, visual: {}}},
        {pos: [12, 6, 15], state: "minecraft:stone"},
        {pos: [13, 6, 15], state: "minecraft:stone"},
        {pos: [14, 6, 9], state: "minecraft:ladder{facing:west,waterlogged:false}"},
        {pos: [14, 6, 15], state: "minecraft:stone"},
        {pos: [15, 6, 9], state: "minecraft:stone"},
        {pos: [15, 6, 10], state: "minecraft:stone"},
        {pos: [15, 6, 11], state: "minecraft:stone"},
        {pos: [15, 6, 12], state: "tl2:cable_bus{light_level:0,waterlogged:false}", nbt: {cable: {gn: {p: 0}, id: "tl2:blue_smart_dense_cable", visual: {channelsDown: 6, channelsUp: 6, connections: ["down", "up"], missingChannel: 0b, powered: 1b}}, facadeWest: {Name: "tl2:quartz_glass"}, hasRedstone: 2, id: "tl2:cable_bus", visual: {}}},
        {pos: [15, 6, 13], state: "tl2:cable_bus{light_level:0,waterlogged:false}", nbt: {cable: {gn: {p: 0}, id: "tl2:white_smart_dense_cable", visual: {channelsDown: 16, channelsUp: 16, connections: ["down", "up"], missingChannel: 0b, powered: 1b}}, facadeWest: {Name: "tl2:quartz_glass"}, hasRedstone: 2, id: "tl2:cable_bus", visual: {}}},
        {pos: [15, 6, 14], state: "minecraft:stone"},
        {pos: [15, 6, 15], state: "minecraft:stone"},
        {pos: [9, 7, 15], state: "minecraft:stone"},
        {pos: [10, 7, 15], state: "minecraft:stone"},
        {pos: [11, 7, 15], state: "minecraft:stone"},
        {pos: [12, 7, 15], state: "minecraft:stone"},
        {pos: [13, 7, 15], state: "minecraft:stone"},
        {pos: [14, 7, 9], state: "minecraft:ladder{facing:west,waterlogged:false}"},
        {pos: [14, 7, 15], state: "minecraft:stone"},
        {pos: [15, 7, 9], state: "minecraft:stone"},
        {pos: [15, 7, 10], state: "minecraft:stone"},
        {pos: [15, 7, 11], state: "minecraft:stone"},
        {pos: [15, 7, 12], state: "tl2:cable_bus{light_level:0,waterlogged:false}", nbt: {cable: {gn: {p: 0}, id: "tl2:blue_smart_dense_cable", visual: {channelsDown: 6, channelsUp: 6, connections: ["down", "up"], missingChannel: 0b, powered: 1b}}, facadeWest: {Name: "minecraft:stone_bricks"}, hasRedstone: 2, id: "tl2:cable_bus", visual: {}}},
        {pos: [15, 7, 13], state: "tl2:cable_bus{light_level:0,waterlogged:false}", nbt: {cable: {gn: {p: 0}, id: "tl2:white_smart_dense_cable", visual: {channelsDown: 16, channelsUp: 16, connections: ["down", "up"], missingChannel: 0b, powered: 1b}}, facadeWest: {Name: "minecraft:stone_bricks"}, hasRedstone: 2, id: "tl2:cable_bus", visual: {}}},
        {pos: [15, 7, 14], state: "minecraft:stone"},
        {pos: [15, 7, 15], state: "minecraft:stone"},
        {pos: [7, 8, 10], state: "minecraft:stone"},
        {pos: [7, 8, 11], state: "minecraft:stone"},
        {pos: [7, 8, 12], state: "minecraft:stone"},
        {pos: [7, 8, 13], state: "minecraft:stone"},
        {pos: [8, 8, 6], state: "minecraft:stone"},
        {pos: [8, 8, 7], state: "minecraft:sea_lantern"},
        {pos: [8, 8, 8], state: "minecraft:sea_lantern"},
        {pos: [8, 8, 9], state: "minecraft:stone"},
        {pos: [8, 8, 10], state: "minecraft:stone"},
        {pos: [8, 8, 11], state: "minecraft:stone"},
        {pos: [8, 8, 12], state: "minecraft:stone"},
        {pos: [8, 8, 13], state: "minecraft:stone"},
        {pos: [8, 8, 14], state: "minecraft:smooth_stone"},
        {pos: [9, 8, 5], state: "minecraft:stone"},
        {pos: [9, 8, 6], state: "minecraft:stone"},
        {pos: [9, 8, 7], state: "minecraft:stone"},
        {pos: [9, 8, 8], state: "minecraft:stone"},
        {pos: [9, 8, 9], state: "minecraft:stone"},
        {pos: [9, 8, 10], state: "minecraft:stone"},
        {pos: [9, 8, 11], state: "minecraft:stone"},
        {pos: [9, 8, 12], state: "minecraft:stone"},
        {pos: [9, 8, 13], state: "minecraft:sea_lantern"},
        {pos: [9, 8, 14], state: "minecraft:smooth_stone"},
        {pos: [9, 8, 15], state: "minecraft:stone"},
        {pos: [10, 8, 1], state: "minecraft:smooth_stone"},
        {pos: [10, 8, 2], state: "minecraft:stone"},
        {pos: [10, 8, 3], state: "minecraft:stone"},
        {pos: [10, 8, 4], state: "minecraft:stone"},
        {pos: [10, 8, 5], state: "minecraft:stone"},
        {pos: [10, 8, 6], state: "minecraft:stone"},
        {pos: [10, 8, 7], state: "minecraft:stone"},
        {pos: [10, 8, 8], state: "minecraft:stone"},
        {pos: [10, 8, 9], state: "minecraft:stone"},
        {pos: [10, 8, 10], state: "minecraft:stone"},
        {pos: [10, 8, 11], state: "minecraft:stone"},
        {pos: [10, 8, 12], state: "minecraft:stone"},
        {pos: [10, 8, 13], state: "minecraft:stone"},
        {pos: [10, 8, 14], state: "minecraft:smooth_stone"},
        {pos: [10, 8, 15], state: "minecraft:stone"},
        {pos: [11, 8, 1], state: "minecraft:smooth_stone"},
        {pos: [11, 8, 2], state: "minecraft:stone"},
        {pos: [11, 8, 3], state: "minecraft:stone"},
        {pos: [11, 8, 4], state: "minecraft:stone"},
        {pos: [11, 8, 5], state: "minecraft:stone"},
        {pos: [11, 8, 6], state: "minecraft:stone"},
        {pos: [11, 8, 7], state: "minecraft:stone"},
        {pos: [11, 8, 8], state: "minecraft:stone"},
        {pos: [11, 8, 9], state: "minecraft:stone"},
        {pos: [11, 8, 10], state: "minecraft:stone"},
        {pos: [11, 8, 11], state: "minecraft:stone"},
        {pos: [11, 8, 12], state: "minecraft:stone"},
        {pos: [11, 8, 13], state: "minecraft:stone"},
        {pos: [11, 8, 14], state: "minecraft:smooth_stone"},
        {pos: [11, 8, 15], state: "minecraft:stone"},
        {pos: [12, 8, 1], state: "minecraft:smooth_stone"},
        {pos: [12, 8, 2], state: "minecraft:stone"},
        {pos: [12, 8, 3], state: "minecraft:stone"},
        {pos: [12, 8, 4], state: "minecraft:stone"},
        {pos: [12, 8, 5], state: "minecraft:stone"},
        {pos: [12, 8, 6], state: "minecraft:stone"},
        {pos: [12, 8, 7], state: "minecraft:stone"},
        {pos: [12, 8, 8], state: "minecraft:stone"},
        {pos: [12, 8, 9], state: "minecraft:stone"},
        {pos: [12, 8, 10], state: "minecraft:stone"},
        {pos: [12, 8, 11], state: "minecraft:stone"},
        {pos: [12, 8, 12], state: "minecraft:stone"},
        {pos: [12, 8, 13], state: "minecraft:stone"},
        {pos: [12, 8, 14], state: "minecraft:smooth_stone"},
        {pos: [12, 8, 15], state: "minecraft:stone"},
        {pos: [13, 8, 1], state: "minecraft:smooth_stone"},
        {pos: [13, 8, 2], state: "minecraft:sea_lantern"},
        {pos: [13, 8, 3], state: "minecraft:stone"},
        {pos: [13, 8, 4], state: "minecraft:stone"},
        {pos: [13, 8, 5], state: "minecraft:stone"},
        {pos: [13, 8, 6], state: "minecraft:stone"},
        {pos: [13, 8, 7], state: "minecraft:stone"},
        {pos: [13, 8, 8], state: "minecraft:stone"},
        {pos: [13, 8, 9], state: "minecraft:stone"},
        {pos: [13, 8, 10], state: "minecraft:stone"},
        {pos: [13, 8, 11], state: "minecraft:stone"},
        {pos: [13, 8, 12], state: "minecraft:stone"},
        {pos: [13, 8, 13], state: "minecraft:sea_lantern"},
        {pos: [13, 8, 14], state: "minecraft:smooth_stone"},
        {pos: [13, 8, 15], state: "minecraft:stone"},
        {pos: [14, 8, 1], state: "minecraft:smooth_stone"},
        {pos: [14, 8, 2], state: "minecraft:smooth_stone"},
        {pos: [14, 8, 3], state: "minecraft:smooth_stone"},
        {pos: [14, 8, 4], state: "minecraft:smooth_stone"},
        {pos: [14, 8, 5], state: "minecraft:smooth_stone"},
        {pos: [14, 8, 6], state: "minecraft:smooth_stone"},
        {pos: [14, 8, 7], state: "minecraft:smooth_stone"},
        {pos: [14, 8, 8], state: "minecraft:smooth_stone"},
        {pos: [14, 8, 9], state: "minecraft:ladder{facing:west,waterlogged:false}"},
        {pos: [14, 8, 10], state: "minecraft:smooth_stone"},
        {pos: [14, 8, 11], state: "minecraft:smooth_stone"},
        {pos: [14, 8, 12], state: "minecraft:smooth_stone"},
        {pos: [14, 8, 13], state: "minecraft:smooth_stone"},
        {pos: [14, 8, 14], state: "minecraft:smooth_stone"},
        {pos: [14, 8, 15], state: "minecraft:stone"},
        {pos: [15, 8, 9], state: "minecraft:stone"},
        {pos: [15, 8, 10], state: "minecraft:stone"},
        {pos: [15, 8, 11], state: "minecraft:stone"},
        {pos: [15, 8, 12], state: "tl2:cable_bus{light_level:0,waterlogged:false}", nbt: {cable: {gn: {p: 0}, id: "tl2:blue_smart_dense_cable", visual: {channelsDown: 6, channelsUp: 6, connections: ["down", "up"], missingChannel: 0b, powered: 1b}}, hasRedstone: 2, id: "tl2:cable_bus", visual: {}}},
        {pos: [15, 8, 13], state: "tl2:cable_bus{light_level:0,waterlogged:false}", nbt: {cable: {gn: {p: 0}, id: "tl2:white_smart_dense_cable", visual: {channelsDown: 16, channelsUp: 16, connections: ["down", "up"], missingChannel: 0b, powered: 1b}}, hasRedstone: 2, id: "tl2:cable_bus", visual: {}}},
        {pos: [15, 8, 14], state: "minecraft:stone"},
        {pos: [15, 8, 15], state: "minecraft:stone"},
        {pos: [7, 9, 8], state: "tl2:wireless_access_point{facing:down,state:has_channel,waterlogged:false}", nbt: {id: "tl2:wireless_access_point", inv: {item0: {}}, proxy: {p: 0}, visual: {}}},
        {pos: [10, 9, 13], state: "tl2:interface", nbt: {fuzzy_mode: "IGNORE_ALL", id: "tl2:interface", priority: 0, proxy: {p: 0}, visual: {}}},
        {pos: [10, 9, 15], state: "minecraft:stone"},
        {pos: [11, 9, 13], state: "tl2:cable_bus{light_level:0,waterlogged:false}", nbt: {cable: {gn: {p: 0}, id: "tl2:white_smart_cable", visual: {channelsUp: 1, connections: ["up"], missingChannel: 0b, powered: 1b}}, hasRedstone: 2, id: "tl2:cable_bus", visual: {}, west: {access: "READ_WRITE", filter_on_extract: "YES", fuzzy_mode: "IGNORE_ALL", gn: {p: 0}, id: "tl2:storage_bus", priority: 0, storage_filter: "EXTRACTABLE_ONLY", visual: {missingChannel: 0b, powered: 1b}}}},
        {pos: [11, 9, 15], state: "minecraft:stone"},
        {pos: [12, 9, 15], state: "minecraft:stone"},
        {pos: [13, 9, 3], state: "minecraft:red_bed{facing:south,occupied:false,part:foot}", nbt: {id: "minecraft:bed"}},
        {pos: [13, 9, 4], state: "minecraft:red_bed{facing:south,occupied:false,part:head}", nbt: {id: "minecraft:bed"}},
        {pos: [13, 9, 5], state: "tl2:cell_workbench{facing:north,spin:0}", nbt: {copy_mode: "CLEAR_ON_REMOVE", id: "tl2:cell_workbench", visual: {}}},
        {pos: [13, 9, 6], state: "tl2:io_port{facing:west,powered:true,spin:0}", nbt: {fullness_mode: "EMPTY", id: "tl2:io_port", inv: {item0: {}, item1: {}, item10: {}, item11: {}, item2: {}, item3: {}, item4: {}, item5: {}, item6: {}, item7: {}, item8: {}, item9: {}}, lastRedstoneState: 1, operation_mode: "EMPTY", proxy: {p: 0}, redstone_controlled: "IGNORE", visual: {}}},
        {pos: [13, 9, 7], state: "tl2:drive{facing:west,spin:0}", nbt: {id: "tl2:drive", inv: {item0: {Count: 1b, id: "tl2:item_storage_cell_4k", tag: {amts: [L; 1L, 1L, 1L, 1L, 1L, 1L, 1L, 1L, 1L, 1L, 1L, 1L, 1L, 1L, 2L, 1L, 2L, 1L, 1L, 8L, 1L, 2L, 1L, 2L, 1L, 1L, 1L, 1L, 1L, 1L, 11L, 1L, 1L, 1L, 2L, 7L, 1729L, 2L, 1L, 1L, 1L, 1L, 1L, 1L, 1L, 1L, 1L, 1L, 1L, 1L, 1L, 1L, 1L, 2L, 1L, 1L, 1L, 1L, 1L, 1L, 1L, 1L, 1L], ic: 1821L, keys: [{"#t": "tl2:i", id: "minecraft:brown_concrete_powder"}, {"#t": "tl2:i", id: "minecraft:magenta_wool"}, {"#t": "tl2:i", id: "minecraft:cyan_concrete"}, {"#t": "tl2:i", id: "minecraft:brown_stained_glass"}, {"#t": "tl2:i", id: "minecraft:cracked_deepslate_bricks"}, {"#t": "tl2:i", id: "minecraft:purple_concrete_powder"}, {"#t": "tl2:i", id: "minecraft:blue_concrete_powder"}, {"#t": "tl2:i", id: "minecraft:nether_brick_slab"}, {"#t": "tl2:i", id: "minecraft:mossy_stone_brick_wall"}, {"#t": "tl2:i", id: "minecraft:crimson_fence"}, {"#t": "tl2:i", id: "minecraft:purpur_pillar"}, {"#t": "tl2:i", id: "minecraft:white_terracotta"}, {"#t": "tl2:i", id: "minecraft:mangrove_wood"}, {"#t": "tl2:i", id: "minecraft:cherry_log"}, {"#t": "tl2:i", id: "minecraft:magenta_concrete_powder"}, {"#t": "tl2:i", id: "minecraft:pink_concrete_powder"}, {"#t": "tl2:i", id: "minecraft:magenta_shulker_box"}, {"#t": "tl2:i", id: "minecraft:waxed_exposed_cut_copper_stairs"}, {"#t": "tl2:i", id: "minecraft:gray_concrete_powder"}, {"#t": "tl2:i", id: "tl2:certus_quartz_dust"}, {"#t": "tl2:i", id: "minecraft:cobbled_deepslate_slab"}, {"#t": "tl2:i", id: "minecraft:dark_oak_stairs"}, {"#t": "tl2:i", id: "minecraft:mossy_stone_brick_stairs"}, {"#t": "tl2:i", id: "minecraft:black_concrete_powder"}, {"#t": "tl2:i", id: "minecraft:andesite_wall"}, {"#t": "tl2:i", id: "minecraft:red_concrete_powder"}, {"#t": "tl2:i", id: "minecraft:stripped_mangrove_log"}, {"#t": "tl2:i", id: "minecraft:birch_fence"}, {"#t": "tl2:i", id: "minecraft:stripped_birch_wood"}, {"#t": "tl2:i", id: "minecraft:white_concrete"}, {"#t": "tl2:i", id: "minecraft:light_blue_concrete"}, {"#t": "tl2:i", id: "minecraft:spruce_trapdoor"}, {"#t": "tl2:i", id: "minecraft:black_glazed_terracotta"}, {"#t": "tl2:i", id: "minecraft:oak_wood"}, {"#t": "tl2:i", id: "minecraft:light_blue_concrete_powder"}, {"#t": "tl2:i", id: "minecraft:spruce_log"}, {"#t": "tl2:i", id: "minecraft:soul_sand"}, {"#t": "tl2:i", id: "minecraft:crimson_stairs"}, {"#t": "tl2:i", id: "minecraft:dark_oak_slab"}, {"#t": "tl2:i", id: "minecraft:brown_shulker_box"}, {"#t": "tl2:i", id: "minecraft:stripped_cherry_wood"}, {"#t": "tl2:i", id: "minecraft:dark_oak_log"}, {"#t": "tl2:i", id: "minecraft:cherry_wood"}, {"#t": "tl2:i", id: "minecraft:weathered_cut_copper_slab"}, {"#t": "tl2:i", id: "minecraft:crimson_pressure_plate"}, {"#t": "tl2:i", id: "minecraft:mangrove_trapdoor"}, {"#t": "tl2:i", id: "minecraft:stripped_warped_stem"}, {"#t": "tl2:i", id: "minecraft:dark_oak_trapdoor"}, {"#t": "tl2:i", id: "minecraft:bamboo_slab"}, {"#t": "tl2:i", id: "minecraft:cherry_stairs"}, {"#t": "tl2:i", id: "minecraft:gold_block"}, {"#t": "tl2:i", id: "minecraft:red_glazed_terracotta"}, {"#t": "tl2:i", id: "minecraft:mossy_stone_bricks"}, {"#t": "tl2:i", id: "minecraft:spruce_wood"}, {"#t": "tl2:i", id: "minecraft:green_concrete"}, {"#t": "tl2:i", id: "minecraft:stripped_cherry_log"}, {"#t": "tl2:i", id: "minecraft:quartz_bricks"}, {"#t": "tl2:i", id: "minecraft:cut_red_sandstone"}, {"#t": "tl2:i", id: "minecraft:orange_concrete_powder"}, {"#t": "tl2:i", id: "minecraft:mangrove_log"}, {"#t": "tl2:i", id: "minecraft:spruce_door"}, {"#t": "tl2:i", id: "minecraft:polished_blackstone_slab"}, {"#t": "tl2:i", id: "minecraft:cherry_slab"}]}}, item1: {Count: 1b, id: "tl2:item_storage_cell_4k", tag: {amts: [L; 1L, 1L, 1L, 1L, 1L, 1L, 1L, 1L, 1L, 1L, 1L, 1L, 1L, 1L, 2L, 1L, 2L, 1L, 1L, 8L, 1L, 2L, 1L, 2L, 1L, 1L, 1L, 1L, 1L, 1L, 11L, 1L, 1L, 1L, 2L, 7L, 1729L, 2L, 1L, 1L, 1L, 1L, 1L, 1L, 1L, 1L, 1L, 1L, 1L, 1L, 1L, 1L, 1L, 2L, 1L, 1L, 1L, 1L, 1L, 1L, 1L, 1L, 1L], ic: 1821L, keys: [{"#t": "tl2:i", id: "minecraft:brown_concrete_powder"}, {"#t": "tl2:i", id: "minecraft:magenta_wool"}, {"#t": "tl2:i", id: "minecraft:cyan_concrete"}, {"#t": "tl2:i", id: "minecraft:brown_stained_glass"}, {"#t": "tl2:i", id: "minecraft:cracked_deepslate_bricks"}, {"#t": "tl2:i", id: "minecraft:purple_concrete_powder"}, {"#t": "tl2:i", id: "minecraft:blue_concrete_powder"}, {"#t": "tl2:i", id: "minecraft:nether_brick_slab"}, {"#t": "tl2:i", id: "minecraft:mossy_stone_brick_wall"}, {"#t": "tl2:i", id: "minecraft:crimson_fence"}, {"#t": "tl2:i", id: "minecraft:purpur_pillar"}, {"#t": "tl2:i", id: "minecraft:white_terracotta"}, {"#t": "tl2:i", id: "minecraft:mangrove_wood"}, {"#t": "tl2:i", id: "minecraft:cherry_log"}, {"#t": "tl2:i", id: "minecraft:magenta_concrete_powder"}, {"#t": "tl2:i", id: "minecraft:pink_concrete_powder"}, {"#t": "tl2:i", id: "minecraft:magenta_shulker_box"}, {"#t": "tl2:i", id: "minecraft:waxed_exposed_cut_copper_stairs"}, {"#t": "tl2:i", id: "minecraft:gray_concrete_powder"}, {"#t": "tl2:i", id: "tl2:certus_quartz_dust"}, {"#t": "tl2:i", id: "minecraft:cobbled_deepslate_slab"}, {"#t": "tl2:i", id: "minecraft:dark_oak_stairs"}, {"#t": "tl2:i", id: "minecraft:mossy_stone_brick_stairs"}, {"#t": "tl2:i", id: "minecraft:black_concrete_powder"}, {"#t": "tl2:i", id: "minecraft:andesite_wall"}, {"#t": "tl2:i", id: "minecraft:red_concrete_powder"}, {"#t": "tl2:i", id: "minecraft:stripped_mangrove_log"}, {"#t": "tl2:i", id: "minecraft:birch_fence"}, {"#t": "tl2:i", id: "minecraft:stripped_birch_wood"}, {"#t": "tl2:i", id: "minecraft:white_concrete"}, {"#t": "tl2:i", id: "minecraft:light_blue_concrete"}, {"#t": "tl2:i", id: "minecraft:spruce_trapdoor"}, {"#t": "tl2:i", id: "minecraft:black_glazed_terracotta"}, {"#t": "tl2:i", id: "minecraft:oak_wood"}, {"#t": "tl2:i", id: "minecraft:light_blue_concrete_powder"}, {"#t": "tl2:i", id: "minecraft:spruce_log"}, {"#t": "tl2:i", id: "minecraft:soul_sand"}, {"#t": "tl2:i", id: "minecraft:crimson_stairs"}, {"#t": "tl2:i", id: "minecraft:dark_oak_slab"}, {"#t": "tl2:i", id: "minecraft:brown_shulker_box"}, {"#t": "tl2:i", id: "minecraft:stripped_cherry_wood"}, {"#t": "tl2:i", id: "minecraft:dark_oak_log"}, {"#t": "tl2:i", id: "minecraft:cherry_wood"}, {"#t": "tl2:i", id: "minecraft:weathered_cut_copper_slab"}, {"#t": "tl2:i", id: "minecraft:crimson_pressure_plate"}, {"#t": "tl2:i", id: "minecraft:mangrove_trapdoor"}, {"#t": "tl2:i", id: "minecraft:stripped_warped_stem"}, {"#t": "tl2:i", id: "minecraft:dark_oak_trapdoor"}, {"#t": "tl2:i", id: "minecraft:bamboo_slab"}, {"#t": "tl2:i", id: "minecraft:cherry_stairs"}, {"#t": "tl2:i", id: "minecraft:gold_block"}, {"#t": "tl2:i", id: "minecraft:red_glazed_terracotta"}, {"#t": "tl2:i", id: "minecraft:mossy_stone_bricks"}, {"#t": "tl2:i", id: "minecraft:spruce_wood"}, {"#t": "tl2:i", id: "minecraft:green_concrete"}, {"#t": "tl2:i", id: "minecraft:stripped_cherry_log"}, {"#t": "tl2:i", id: "minecraft:quartz_bricks"}, {"#t": "tl2:i", id: "minecraft:cut_red_sandstone"}, {"#t": "tl2:i", id: "minecraft:orange_concrete_powder"}, {"#t": "tl2:i", id: "minecraft:mangrove_log"}, {"#t": "tl2:i", id: "minecraft:spruce_door"}, {"#t": "tl2:i", id: "minecraft:polished_blackstone_slab"}, {"#t": "tl2:i", id: "minecraft:cherry_slab"}]}}, item2: {Count: 1b, id: "tl2:item_storage_cell_4k", tag: {amts: [L; 1L, 1L, 1L, 1L, 1L, 1L, 1L, 1L, 1L, 1L, 1L, 1L, 1L, 1L, 2L, 1L, 2L, 1L, 1L, 8L, 1L, 2L, 1L, 2L, 1L, 1L, 1L, 1L, 1L, 1L, 11L, 1L, 1L, 1L, 2L, 7L, 1729L, 2L, 1L, 1L, 1L, 1L, 1L, 1L, 1L, 1L, 1L, 1L, 1L, 1L, 1L, 1L, 1L, 2L, 1L, 1L, 1L, 1L, 1L, 1L, 1L, 1L, 1L], ic: 1821L, keys: [{"#t": "tl2:i", id: "minecraft:brown_concrete_powder"}, {"#t": "tl2:i", id: "minecraft:magenta_wool"}, {"#t": "tl2:i", id: "minecraft:cyan_concrete"}, {"#t": "tl2:i", id: "minecraft:brown_stained_glass"}, {"#t": "tl2:i", id: "minecraft:cracked_deepslate_bricks"}, {"#t": "tl2:i", id: "minecraft:purple_concrete_powder"}, {"#t": "tl2:i", id: "minecraft:blue_concrete_powder"}, {"#t": "tl2:i", id: "minecraft:nether_brick_slab"}, {"#t": "tl2:i", id: "minecraft:mossy_stone_brick_wall"}, {"#t": "tl2:i", id: "minecraft:crimson_fence"}, {"#t": "tl2:i", id: "minecraft:purpur_pillar"}, {"#t": "tl2:i", id: "minecraft:white_terracotta"}, {"#t": "tl2:i", id: "minecraft:mangrove_wood"}, {"#t": "tl2:i", id: "minecraft:cherry_log"}, {"#t": "tl2:i", id: "minecraft:magenta_concrete_powder"}, {"#t": "tl2:i", id: "minecraft:pink_concrete_powder"}, {"#t": "tl2:i", id: "minecraft:magenta_shulker_box"}, {"#t": "tl2:i", id: "minecraft:waxed_exposed_cut_copper_stairs"}, {"#t": "tl2:i", id: "minecraft:gray_concrete_powder"}, {"#t": "tl2:i", id: "tl2:certus_quartz_dust"}, {"#t": "tl2:i", id: "minecraft:cobbled_deepslate_slab"}, {"#t": "tl2:i", id: "minecraft:dark_oak_stairs"}, {"#t": "tl2:i", id: "minecraft:mossy_stone_brick_stairs"}, {"#t": "tl2:i", id: "minecraft:black_concrete_powder"}, {"#t": "tl2:i", id: "minecraft:andesite_wall"}, {"#t": "tl2:i", id: "minecraft:red_concrete_powder"}, {"#t": "tl2:i", id: "minecraft:stripped_mangrove_log"}, {"#t": "tl2:i", id: "minecraft:birch_fence"}, {"#t": "tl2:i", id: "minecraft:stripped_birch_wood"}, {"#t": "tl2:i", id: "minecraft:white_concrete"}, {"#t": "tl2:i", id: "minecraft:light_blue_concrete"}, {"#t": "tl2:i", id: "minecraft:spruce_trapdoor"}, {"#t": "tl2:i", id: "minecraft:black_glazed_terracotta"}, {"#t": "tl2:i", id: "minecraft:oak_wood"}, {"#t": "tl2:i", id: "minecraft:light_blue_concrete_powder"}, {"#t": "tl2:i", id: "minecraft:spruce_log"}, {"#t": "tl2:i", id: "minecraft:soul_sand"}, {"#t": "tl2:i", id: "minecraft:crimson_stairs"}, {"#t": "tl2:i", id: "minecraft:dark_oak_slab"}, {"#t": "tl2:i", id: "minecraft:brown_shulker_box"}, {"#t": "tl2:i", id: "minecraft:stripped_cherry_wood"}, {"#t": "tl2:i", id: "minecraft:dark_oak_log"}, {"#t": "tl2:i", id: "minecraft:cherry_wood"}, {"#t": "tl2:i", id: "minecraft:weathered_cut_copper_slab"}, {"#t": "tl2:i", id: "minecraft:crimson_pressure_plate"}, {"#t": "tl2:i", id: "minecraft:mangrove_trapdoor"}, {"#t": "tl2:i", id: "minecraft:stripped_warped_stem"}, {"#t": "tl2:i", id: "minecraft:dark_oak_trapdoor"}, {"#t": "tl2:i", id: "minecraft:bamboo_slab"}, {"#t": "tl2:i", id: "minecraft:cherry_stairs"}, {"#t": "tl2:i", id: "minecraft:gold_block"}, {"#t": "tl2:i", id: "minecraft:red_glazed_terracotta"}, {"#t": "tl2:i", id: "minecraft:mossy_stone_bricks"}, {"#t": "tl2:i", id: "minecraft:spruce_wood"}, {"#t": "tl2:i", id: "minecraft:green_concrete"}, {"#t": "tl2:i", id: "minecraft:stripped_cherry_log"}, {"#t": "tl2:i", id: "minecraft:quartz_bricks"}, {"#t": "tl2:i", id: "minecraft:cut_red_sandstone"}, {"#t": "tl2:i", id: "minecraft:orange_concrete_powder"}, {"#t": "tl2:i", id: "minecraft:mangrove_log"}, {"#t": "tl2:i", id: "minecraft:spruce_door"}, {"#t": "tl2:i", id: "minecraft:polished_blackstone_slab"}, {"#t": "tl2:i", id: "minecraft:cherry_slab"}]}}, item3: {Count: 1b, id: "tl2:item_storage_cell_4k", tag: {amts: [L; 1L, 1L, 1L, 1L, 1L, 1L, 1L, 1L, 1L, 1L, 1L, 1L, 1L, 1L, 2L, 1L, 2L, 1L, 1L, 8L, 1L, 2L, 1L, 2L, 1L, 1L, 1L, 1L, 1L, 1L, 11L, 1L, 1L, 1L, 2L, 7L, 1729L, 2L, 1L, 1L, 1L, 1L, 1L, 1L, 1L, 1L, 1L, 1L, 1L, 1L, 1L, 1L, 1L, 2L, 1L, 1L, 1L, 1L, 1L, 1L, 1L, 1L, 1L], ic: 1821L, keys: [{"#t": "tl2:i", id: "minecraft:brown_concrete_powder"}, {"#t": "tl2:i", id: "minecraft:magenta_wool"}, {"#t": "tl2:i", id: "minecraft:cyan_concrete"}, {"#t": "tl2:i", id: "minecraft:brown_stained_glass"}, {"#t": "tl2:i", id: "minecraft:cracked_deepslate_bricks"}, {"#t": "tl2:i", id: "minecraft:purple_concrete_powder"}, {"#t": "tl2:i", id: "minecraft:blue_concrete_powder"}, {"#t": "tl2:i", id: "minecraft:nether_brick_slab"}, {"#t": "tl2:i", id: "minecraft:mossy_stone_brick_wall"}, {"#t": "tl2:i", id: "minecraft:crimson_fence"}, {"#t": "tl2:i", id: "minecraft:purpur_pillar"}, {"#t": "tl2:i", id: "minecraft:white_terracotta"}, {"#t": "tl2:i", id: "minecraft:mangrove_wood"}, {"#t": "tl2:i", id: "minecraft:cherry_log"}, {"#t": "tl2:i", id: "minecraft:magenta_concrete_powder"}, {"#t": "tl2:i", id: "minecraft:pink_concrete_powder"}, {"#t": "tl2:i", id: "minecraft:magenta_shulker_box"}, {"#t": "tl2:i", id: "minecraft:waxed_exposed_cut_copper_stairs"}, {"#t": "tl2:i", id: "minecraft:gray_concrete_powder"}, {"#t": "tl2:i", id: "tl2:certus_quartz_dust"}, {"#t": "tl2:i", id: "minecraft:cobbled_deepslate_slab"}, {"#t": "tl2:i", id: "minecraft:dark_oak_stairs"}, {"#t": "tl2:i", id: "minecraft:mossy_stone_brick_stairs"}, {"#t": "tl2:i", id: "minecraft:black_concrete_powder"}, {"#t": "tl2:i", id: "minecraft:andesite_wall"}, {"#t": "tl2:i", id: "minecraft:red_concrete_powder"}, {"#t": "tl2:i", id: "minecraft:stripped_mangrove_log"}, {"#t": "tl2:i", id: "minecraft:birch_fence"}, {"#t": "tl2:i", id: "minecraft:stripped_birch_wood"}, {"#t": "tl2:i", id: "minecraft:white_concrete"}, {"#t": "tl2:i", id: "minecraft:light_blue_concrete"}, {"#t": "tl2:i", id: "minecraft:spruce_trapdoor"}, {"#t": "tl2:i", id: "minecraft:black_glazed_terracotta"}, {"#t": "tl2:i", id: "minecraft:oak_wood"}, {"#t": "tl2:i", id: "minecraft:light_blue_concrete_powder"}, {"#t": "tl2:i", id: "minecraft:spruce_log"}, {"#t": "tl2:i", id: "minecraft:soul_sand"}, {"#t": "tl2:i", id: "minecraft:crimson_stairs"}, {"#t": "tl2:i", id: "minecraft:dark_oak_slab"}, {"#t": "tl2:i", id: "minecraft:brown_shulker_box"}, {"#t": "tl2:i", id: "minecraft:stripped_cherry_wood"}, {"#t": "tl2:i", id: "minecraft:dark_oak_log"}, {"#t": "tl2:i", id: "minecraft:cherry_wood"}, {"#t": "tl2:i", id: "minecraft:weathered_cut_copper_slab"}, {"#t": "tl2:i", id: "minecraft:crimson_pressure_plate"}, {"#t": "tl2:i", id: "minecraft:mangrove_trapdoor"}, {"#t": "tl2:i", id: "minecraft:stripped_warped_stem"}, {"#t": "tl2:i", id: "minecraft:dark_oak_trapdoor"}, {"#t": "tl2:i", id: "minecraft:bamboo_slab"}, {"#t": "tl2:i", id: "minecraft:cherry_stairs"}, {"#t": "tl2:i", id: "minecraft:gold_block"}, {"#t": "tl2:i", id: "minecraft:red_glazed_terracotta"}, {"#t": "tl2:i", id: "minecraft:mossy_stone_bricks"}, {"#t": "tl2:i", id: "minecraft:spruce_wood"}, {"#t": "tl2:i", id: "minecraft:green_concrete"}, {"#t": "tl2:i", id: "minecraft:stripped_cherry_log"}, {"#t": "tl2:i", id: "minecraft:quartz_bricks"}, {"#t": "tl2:i", id: "minecraft:cut_red_sandstone"}, {"#t": "tl2:i", id: "minecraft:orange_concrete_powder"}, {"#t": "tl2:i", id: "minecraft:mangrove_log"}, {"#t": "tl2:i", id: "minecraft:spruce_door"}, {"#t": "tl2:i", id: "minecraft:polished_blackstone_slab"}, {"#t": "tl2:i", id: "minecraft:cherry_slab"}]}},